Workbook
Name _Toc450375517: '7.1'!$A$2
Name _Toc450375517: '7.2'!$A$2
Name _Toc450375517: '7.3'!$A$2
Name _Toc450375517: '7.6'!$A$2
Name _Toc450456886: '7.4'!$A$2
Name _Toc450456886: '7.5'!$A$2

Sheet IDX
B2: Senegal
B3: MICS Plus
B4: 2026
B5: Wave 1
B7: Content
B9: Survey and sample characteristics | H9: Child discipline
B10: ='1.1a'!A1 -> Table 1.1a Response rates (after substitution, unweighted) | H10: ='5.1'!A1 -> Table 5.1 Child discipline
B11: ='1.1b'!A1 -> Table 1.1b Response rates (before substitution, unweighted) | H11: ='5.2'!A1 -> Table 5.2 Attitudes toward physical punishment
B12: ='1.2'!A1 -> Table 1.2 Average number of call attempts (unweighted)
B13: ='1.3'!A1 -> Table 1.3 Number of call attempts (unweighted) | H13: Child labor
B14: ='1.4'!A1 -> Table 1.4 Duration of interviews (unweighted) | H14: ='6.1'!A1 -> Table 6.1 Children's involvement in economic activities
B15: ='2.1'!A1 -> Table 2.1 Housing characteristics | H15: ='6.2'!A1 -> Table 6.2 Children's involvement in household chores
B16: ='2.1a'!A1 -> Table 2.1a Sources of electricity | H16: ='6.3'!A1 -> Table 6.3 Child labour
B17: ='2.1b'!A1 -> Table 2.1b Household and personal assets | H17: ='6.4'!A1 -> Table 6.4 Hazardous work
B18: ='2.1c'!A1 -> Table 2.1c Wealth quintiles
B19: ='2.2'!A1 -> Table 2.2 Household composition | H19: Water and Sanitation
B20: ='2.3'!A1 -> Table 2.3 Age distribution of household population by sex (5-year age groups) | H20: ='7.1'!A1 -> Table 7.1 Use of improved and unimproved water sources
B21: ='2.4'!A1 -> Table 2.4 Birth date reporting | H21: ='7.2'!A1 -> Table 7.2 Use of basic and limited drinking water services
B22: ='3.1'!A1 -> Table 3.1 Highest education of household population age 3 years or above | H22: ='7.3'!A1 -> Table 7.3 Availability of sufficient drinking water when needed
B23: ='3.2'!A1 -> Table 3.2 Formal education of household members age 3-24 years | H23: ='7.4'!A1 -> Table 7.4 Use of improved and unimproved sanitation facilities
B24: ='3.3'!A1 -> Table 3.3 Non-formal education of household members age 6 years or above | H24: ='7.5'!A1 -> Table 7.5 Use of basic and limited sanitation services
H25: ='7.6'!A1 -> Table 7.6 Handwashing facility and availability of water and soap to wash hands when needed
B26: Food Insecurity Experience
B27: ='4.1'!A1 -> Table 4.1 Food Insecurity Experience Scale (FIES)

Sheet Preparation File
A1: # Preparation contract: micsPlusTableR supplies hh_path and hl_path, makes its # declared imports available, and collects hh, hl, and extra-table objects. # Do not source external package or function bootstrap scripts from this file. hh <- haven::read_sav(hh_path) |> arrange(HH1, HH2, HH0, HH0A) |> mutate( hhweightA = ifelse(is.na(hhweightA), 0, hhweightA), hhweightB = ifelse(is.na(hhweightB), 0, hhweightB) ) hl <- haven::read_sav(hl_path) hl <- hl |> mutate(HHID = HH0*1000000 + HH1*1000 + HH2*10 + HH0A) hh <- hh |> mutate(HHID = HH0*1000000 + HH1*1000 + HH2*10 + HH0A) hh <- hh |> mutate(total = 1) hl <- hl |> mutate(total = 1)
A2: # Add variables from hh to hl hh_add <- hh |> select(HHID, HLnum, headed, headsex, headage, headethnic, headlang, headrelig) hl <- hl |> left_join(hh_add, by = "HHID")
A3: # Add variables from hl to hh hl_add <- hl |> select(HHID, HL1, ED4, ED9) hh <- hh |> left_join(hl_add, by = c("HHID", "RS2A" = "HL1"))

Sheet Define
A1: id | B1: code
A2: ea | B2: mutate(ea = if_else(CL1A == 1 | CL1B == 1 | CL1C == 1 | CL1X == 1, 1, 0))
A3: hhc | B3: mutate(hhc = if_else(CL7 == 1 | CL9 == 1 | CL11A == 1 | CL11B == 1 | CL11C == 1 | CL11D == 1 | CL11E == 1 | CL11F == 1 | CL11X == 1, 1, 0))
A4: CL8_CL10_CL13 | B4: mutate(across( c(CL8, CL10, CL13), ~ if_else(.x %in% c(97, 98, 99), 0, .x) ))
A5: hhc21less | B5: mutate(hhc21less = if_else( hhc == 1 & (!is.na(CL8) | !is.na(CL10) | !is.na(CL13)) & rowSums(cbind(CL8, CL10, CL13), na.rm = TRUE) < 21, 1, 0, missing = 0 ))
A6: hhc21more | B6: mutate(hhc21more = if_else( hhc == 1 & rowSums(cbind(CL8, CL10, CL13), na.rm = TRUE) >= 21, 1, 0, missing = 0 ))
A7: ea1more | B7: mutate(ea1more = if_else( ea == 1 & CL3 >= 1 & CL3 < 97, 1, 0, missing = 0 ))
A8: ea14less | B8: mutate(ea14less = if_else( ea == 1 & CL3 < 14, 1, 0, missing = 0 ))

Sheet 1.1a
A1: Table 1.1a Response rates (after substitution, unweighted) | G1: IDX
A2: Number of households by interview results, by area of residence, Senegal MICS Plus 2026, Wave 1
C3: Total | D3: Area
D4: Urban | E4: Rural
B5: hh.sav filter(aftersub == 1) | C5: total == 1 | D5: area == 1 | E5: area == 2
A7: Households sampled | B7: total == 1 | C7: n_unw
A8: Interviewed | B8: HH17 %in% c(0,1)
A9: No consent for next wave | B9: HH17 == 0
A10: With consent for next wave | B10: HH17 == 1
A11: Refused | B11: HH17 %in% c(2,3)
A12: No consent for next wave | B12: HH17 == 2
A13: With consent for next wave | B13: HH17 == 3
A14: No eligible respondent | B14: HH17 == 4
A15: Phone number(s) does not belong to sampled household | B15: HH17 == 5
A16: Phone number(s) inactive | B16: HH17 == 6
A17: Respondent busy / postponed | B17: HH17 == 7
A18: No response after repeated call attempts or phone(s) turned off | B18: HH17 == 8
A19: No phone number available for sampled household | B19: HH17 == 88
A20: Other | B20: HH17 == 96
A22: Response rate | B22: HH17 %in% c(0,1) | C22: mean_unw

Sheet 1.1b
A1: Table 1.1b Response rates (before substitution, unweighted) | G1: IDX
A2: Number of households by interview results, by area of residence, Senegal MICS Plus 2026, Wave 1
C3: Total | D3: Area
D4: Urban | E4: Rural
B5: hh.sav filter(beforesub == 1) | C5: total == 1 | D5: area == 1 | E5: area == 2
A7: Households sampled | B7: total == 1 | C7: n_unw
A8: Interviewed | B8: HH17 %in% c(0,1)
A9: No consent for next wave | B9: HH17 == 0
A10: With consent for next wave | B10: HH17 == 1
A11: Refused | B11: HH17 %in% c(2,3)
A12: No consent for next wave | B12: HH17 == 2
A13: With consent for next wave | B13: HH17 == 3
A14: No eligible respondent | B14: HH17 == 4
A15: Phone number(s) does not belong to sampled household | B15: HH17 == 5
A16: Phone number(s) inactive | B16: HH17 == 6
A17: Respondent busy / postponed | B17: HH17 == 7
A18: No response after repeated call attempts or phone(s) turned off | B18: HH17 == 8
A19: No phone number available for sampled household | B19: HH17 == 88
A20: Other | B20: HH17 == 96
A22: Response rate | B22: HH17 %in% c(0,1) | C22: mean_unw

Sheet 1.2
A1: Table 1.2 Average number of call attempts (unweighted) | G1: IDX
A2: Average number of call attempts by interview resultsA, by area of residence, Senegal MICS Plus 2026, Wave 1
C3: Total | D3: Area
D4: Urban | E4: Rural
B5: hh.sav filter(aftersub == 1 & HH17 != 88) | C5: total == 1 | D5: area == 1 | E5: area == 2
A7: Total | B7: total == 1 | C7: mean_unw(CAnum)
A9: Interviewed | B9: HH17 %in% c(0,1)
A10: No consent for next wave | B10: HH17 == 0
A11: With consent for next wave | B11: HH17 == 1
A12: Refused | B12: HH17 %in% c(2,3)
A13: No consent for next wave | B13: HH17 == 2
A14: With consent for next wave | B14: HH17 == 3
A15: No eligible respondent | B15: HH17 == 4
A16: Phone number(s) does not belong to sampled household | B16: HH17 == 5
A17: Phone number(s) inactive | B17: HH17 == 6
A18: Respondent busy/postponed | B18: HH17 == 7
A19: No response after repeated call attempts or phone number(s) turned off | B19: HH17 == 8
A20: Other | B20: HH17 == 96
A21: A It does not include households with the following response codes: No phone number available for sampled household

Sheet 1.3
A1: Table 1.3 Number of call attempts (unweighted) | I1: IDX
A2: Percent and frequency of households by number of call attempts and completion status of interview, Senegal MICS Plus 2026, Wave 1
C3: Completed interviews | F3: Incomplete interviewsA
C4: Number | D4: Percent | F4: Number | G4: Percent
B5: hh.sav filter(aftersub == 1 & HH17 != 88) | C5: HH17 %in% c(0,1) | F5: !(HH17 %in% c(0,1))
A7: Total | B7: total == 1 | C7: n_unw | D7: p_unw(100) | F7: n_unw | G7: p_unw(100)
A9: 1 | B9: CAnum == 1
A10: 2 | B10: CAnum == 2
A11: 3 | B11: CAnum == 3
A12: 4 | B12: CAnum == 4
A13: 5 | B13: CAnum == 5
A14: 6 | B14: CAnum == 6
A15: 7 | B15: CAnum == 7
A16: 8 | B16: CAnum == 8
A17: 9 | B17: CAnum == 9
A18: 10+ | B18: CAnum >= 10
A19: A It does not include households with the following response codes: No phone number available for sampled household

Sheet 1.4
A1: Table 1.4 Duration of interviews (unweighted) | G1: IDX
A2: Mean and median duration of interviews in minutes, Senegal MICS Plus 2026, Wave 1
C3: Duration of interviews (minutes) | E3: Number of householdsA
C4: Mean | D4: Median
B5: hh.sav filter(HH17 %in% c(0,1) & intduration != 97) | C5: total == 1 | D5: total == 1 | E5: total == 1
A7: Total | B7: total == 1 | C7: mean_unw(intduration) | D7: median_unw(intduration) | E7: n_unw
A9: Area
A10: Urban | B10: area == 1
A11: Rural | B11: area == 2
A12: Sex of respondent
A13: Male | B13: respsex == 1
A14: Female | B14: respsex == 2
A15: Age of respondent
A16: <18 | B16: respage < 18
A17: 18-34 | B17: between(respage,18,34)
A18: 35-64 | B18: between(respage,35,64)
A19: 65-84 | B19: between(respage,65,84)
A20: 85+ | B20: between(respage,85,95)
A21: Education of respondent
A22: Pre-primary or none | B22: resped == 0
A23: Primary (Elementary) | B23: resped == 1
A24: Lower secondary (Moyen) | B24: resped == 2
A25: Upper secondary (Secondaire / Lycée) | B25: resped == 3
A26: Higher education | B26: resped == 4
A27: DK / Missing | B27: resped == 8
A28: Number of household members
A29: 1-3 | B29: between(HLnum,1,3)
A30: 4-6 | B30: between(HLnum,4,6)
A31: 7-9 | B31: between(HLnum,7,9)
A32: 10-12 | B32: between(HLnum,10,12)
A33: 13-15 | B33: between(HLnum,13.15)
A34: 16+ | B34: HLnum >= 16
A35: A XXX households are excluded from the calculation of mean and median durations of interview, due to interrupted calls and inconsistent information

Sheet 2.1
A1: Table 2.1 Housing characteristics | G1: IDX
A2: Percent distribution of households by selected housing characteristics, by area of residence, Senegal MICS Plus 2026, Wave 1
C3: Total | D3: Area
D4: Urban | E4: Rural
B5: hh.sav filter(HH17 %in% c(0,1)) weight by hhweightA | C5: total == 1 | D5: area == 1 | E5: area == 2
A7: Total | B7: total == 1 | C7: p(100)
A9: Electricity
A10: Yes | B10: CH8 == 1
A11: No | B11: CH8 == 2
A12: Missing | B12: CH8 == 99
A13: Internet access at home
A14: Yes | B14: CH13 == 1 | CH13B == 1
A15: No | B15: (CH13 == 2 & is.na(CH13B)) | CH13B == 2
A16: DK/ Missing | B16: CH13 == 9 | CH13B >= 8
A17: Number of rooms used for sleeping
A18: 1-2 | B18: between(CH6,1,2)
A19: 3-4 | B19: between(CH6,3.4)
A20: 5-6 | B20: between(CH6,5,6)
A21: 7+ | B21: between(CH6,7,96)
A22: Inconsistent / Missing | B22: CH6 >= 97
A24: Percentage with access to consistent sources of electricity | B24: HC8B %in% c(11,21,31) | C24: p
A26: Mean number of persons per room used for sleeping | B26: mutate(perssleeproom = HLnum / CH6) CH6 < 97 | C26: mean(perssleeproom)
A28: Number of households | B28: total == 1 | C28: n

Sheet 2.1a
A1: Table 2.1a Sources of electricity | G1: IDX
A2: Percentage of households with electricity by sources, by area of residence, Senegal MICS Plus 2026, Wave 1
C3: Total | D3: Area
D4: Urban | E4: Rural
B5: hh.sav filter(CH8 == 1) weight by hhweightA | C5: total == 1 | D5: area == 1 | E5: area == 2
A7: Sources of electricityA
A8: National / Interconnected grid | B8: HC8AA = "A"
A9: Local mini grid | B9: HC8AB = "B"
A10: Solar home system | B10: HC8AC = "C"
A11: Solar lantern | B11: HC8AD = "D"
A12: Electric generator | B12: HC8AE = "E"
A13: Rechargeable battery | B13: HC8AF = "F"
A14: Dry cell battery / torch | B14: HC8AG = "G"
A15: Other | B15: HC8AX = "X"
A16: DK / Missing | B16: HC8AZ = "Z" | HC8ANR == "?"
A18: Number of households with electricity | B18: total == 1
A19: A The percentage for electricity in Table 2.1 is calculated for all households, and, in this table, the sum of the percentage by sources of electricity can be over 100 percent as multiple answer options were possible.

Sheet 2.1b
A1: Table 2.1b Household and personal assets | G1: IDX
A2: Percentage of households by ownership of selected household and personal assets, by area of residence, Senegal MICS Plus 2026, Wave 1
C3: Total | D3: Area
D4: Urban | E4: Rural
B5: hh.sav filter(HH17 %in% c(0,1)) weight by hhweightA | C5: total == 1 | D5: area == 1 | E5: area == 2
A7: Percentage that own a
A8: Fixed telephone line | B8: CH7A == 1 | C8: p
A9: Radio | B9: CH7B == 1
A10: Gas stove | B10: CH7C == 1
A11: Improved hearth | B11: CH7D == 1
A12: Television | B12: CH9A == 1
A13: Refrigerator | B13: CH9B == 1
A14: MMDS/TV5 antenna | B14: CH9C == 1
A15: Canal subscription | B15: CH9D == 1
A16: Washing machine | B16: CH9E == 1
A17: Electric stove or cooker | B17: CH9F == 1
A18: Video or CD/DVD player | B18: CH9G == 1
A19: Air conditioner | B19: CH9H == 1
A20: Wi-fi router | B20: CH9I == 1
A21: Percentage where at least one member owns or has a
A22: Wristwatch | B22: CH10A == 1
A23: Bicycle | B23: CH10B == 1
A24: Motorcycle or scooter | B24: CH10C == 1
A25: Animal-drawn cart | B25: CH10D == 1
A26: Car, truck or van | B26: CH10E == 1
A27: Boat with a motor | B27: CH10F == 1
A28: Plow | B28: CH10G == 1
A29: Fishing canoe/net | B29: CH10H == 1
A30: Tricycle | B30: CH10I == 1
A31: Desktop / laptop / tablet or similar computer | B31: CH11 == 1
A32: Mobile telephone | B32: CH12 == 1
A33: Smartphone | B33: CH12A == 1
A34: Account in a bank or other financial institution | B34: CH19 == 1
A35: Percentage where at least one member use a
A36: Mobile phone to make financial transcations either through a bank or mobile service | B36: CH19 == 1
A38: Number of households | B38: total == 1 | C38: n

Sheet 2.1c
A1: Table 2.1c Wealth quintiles | K1: IDX
A2: Percent distribution of household population, by wealth index quintile, Senegal MICS Plus 2026, Wave 1
C3: Percent distribution by wealth index quintiles | H3: Total | I3: Number of household members
C4: Poorest | D4: Second | E4: Middle | F4: Fourth | G4: Richest
B5: hl.sav filter(HL7 %in% c(1,NA)) weight by hhweightA | C5: windex5 == 1 | D5: windex5 == 2 | E5: windex5 == 3 | F5: windex5 == 4 | G5: windex5 == 5 | H5: 100 | I5: total == 1
A7: Total | B7: total == 1 | C7: p | H7: 100 | I7: n
A9: Area
A10: Urban | B10: area == 1 | H10: 100
A11: Rural | B11: area == 2 | H11: 100

Sheet 2.2
A1: Table 2.2 Household composition | G1: IDX
A2: Percent and frequency distribution of households, Senegal MICS Plus 2026, Wave 1
C3: Weighted percent | D3: Number of households
D4: Weighted | E4: Unweighted
B5: hh.sav filter(HH17 %in% c(0,1)) weight by hhweightA | C5: total == 1 | D5: total == 1 | E5: total == 1
A7: Total | B7: total == 1 | C7: p(100) | D7: n | E7: n_unw
A9: Area
A10: Urban | B10: area == 1
A11: Rural | B11: area == 2
A12: Sex of household head
A13: Male | B13: headsex == 1
A14: Female | B14: headsex == 2
A15: Age of household head
A16: <18 | B16: headage < 18
A17: 18-34 | B17: between(headage,18,34)
A18: 35-64 | B18: between(headage,35,64)
A19: 65-84 | B19: between(headage,65,84)
A20: 85+ | B20: between(headage,85,95)
A21: Education of household head
A22: Pre-primary or none | B22: headed == 0
A23: Primary | B23: headed == 1
A24: Lower secondary (Moyen) | B24: headed == 2
A25: Upper secondary (Secondaire / Lycée) | B25: headed == 3
A26: Higher education | B26: headed == 4
A27: DK / Missing | B27: headed == 8
A28: Mother tongue / native language of household headA
A29: French | B29: CH5A == 1
A30: Wolof | B30: CH5A == 2
A31: Poular | B31: CH5A == 3
A32: Serer | B32: CH5A == 4
A33: Diola | B33: CH5A == 5
A34: Mandingue | B34: CH5A == 6
A35: Soninke | B35: CH5A == 7
A36: Other | B36: CH5A == 96
A37: Missing | B37: CH5A == 99
A38: Ethnicity of household headB
A39: Wolof | B39: CH5B == 1
A40: Poular | B40: CH5B == 2
A41: Serer | B41: CH5B == 3
A42: Mandingue | B42: CH5B == 4
...

Sheet 2.3
A1: Table 2.3 Age distribution of household population by sex (5-year age groups) | L1: IDX
A2: Percent and frequency distribution of household population, by 5-year age groups and sex, Senegal MICS Plus 2026, Wave 1
C3: Males | F3: Females | I3: Total
C4: Number | D4: Percent | F4: Number | G4: Percent | I4: Number | J4: Percent
B5: hl.sav filter(HL7 %in% c(1,NA)) weight by hhweightA | C5: HL4 == 1 | F5: HL4 == 2 | I5: total == 1
A7: Total | B7: total == 1 | C7: n | D7: p | F7: n | G7: p | I7: n | J7: p
A9: Age
A10: 0-4 | B10: between(HL6,0,4)
A11: 5-9 | B11: between(HL6,5,9)
A12: 10-14 | B12: between(HL6,10,14)
A13: 15-19 | B13: between(HL6,15,19)
A14: 20-24 | B14: between(HL6,20,24)
A15: 25-29 | B15: between(HL6,25,29)
A16: 30-34 | B16: between(HL6,30,34)
A17: 35-39 | B17: between(HL6,35,39)
A18: 40-44 | B18: between(HL6,40,44)
A19: 45-49 | B19: between(HL6,45,49)
A20: 50-54 | B20: between(HL6,50,54)
A21: 55-59 | B21: between(HL6,55,59)
... A27: 85+ | B27: between(HL6,85,95)

Sheet 2.4
A1: Table 2.4 Birth date reporting | J1: IDX
A2: Percent distribution of household population, by completeness of reporting of date of birth and ageA, Senegal MICS Plus 2026, Wave 1
C3: Percent distribution by completeness of reporting of date of birth and age | G3: Total | H3: Number of household members
C4: Year and month of birth (calculated age) | D4: Reported age
D5: Year of birth only | E5: Month of birth only | F5: Neither year nor month of birth
B6: hl.sav filter(HL7 %in% c(1,NA)) weight by hhweightA | C6: HL5M < 98 & HL5Y < 9998 | D6: HL5Y < 9998 & HL5M >= 98 | E6: HL5Y >= 9998 & HL5M < 98 | F6: HL5M >= 98 & HL5Y >= 9998 | G6: 100 | H6: total == 1
A8: Total | B8: total == 1 | C8: p | G8: 100 | H8: n
A10: Area
A11: Urban | B11: area == 1 | G11: 100
A12: Rural | B12: area == 2 | G12: 100
A13: Age
A14: 0-17 | B14: between(HL6,0,17) | G14: 100
A15: 18-34 | B15: between(HL6,18,34) | G15: 100
A16: 35-64 | B16: between(HL6,35,64) | G16: 100
A17: 65-84 | B17: between(HL6,65,84) | G17: 100
A18: 85+ | B18: between(HL6,85,95) | G18: 100
A19: A In MICS Plus questionnaire, age of a household member is calculated if both year and month of birth information available and only asked if either year or month of birth information not available. Thus, for all household members, age information would be available.

Sheet 3.1
A1: Table 3.1 Highest education of household population age 3 years or above | N1: IDX
A2: Percentage of household members age 3 years or above who ever attended non-formal education, and percent distribution of household members by highest level of formal education attended, Senegal MICS Plus 2026, Wave 1
C3: Percentage who ever attended non-formal education | E3: Percent distribution by level of highest formal education | K3: Total | L3: Number of household members age 3 years or above
E4: Pre-primary or none | F4: Primary | G4: Lower secondary (Moyen) | H4: Upper secondary (Secondaire / Lycée) | I4: Higher education | J4: DK / Missing
B5: hl.sav filter(HL7 %in% c(1,NA) & between(HL6,3,95)) weight by hhweightA | C5: ED4A == 1 | E5: edlevel == 0 | F5: edlevel == 1 | G5: edlevel == 2 | H5: edlevel == 3 | I5: edlevel == 4 | J5: edlevel == 8 | K5: 100 | L5: total == 1 | M5: total == 1
A7: Total | B7: total == 1 | C7: p | K7: 100 | L7: n | M7: n_unw
A9: Area
A10: Urban | B10: area == 1 | K10: 100
A11: Rural | B11: area == 2 | K11: 100
A12: Sex
A13: Male | B13: HL4 == 1 | K13: 100
A14: Female | B14: HL4 == 2 | K14: 100
A15: Age
A16: 3-17 | B16: between(HL6,3,17) | K16: 100
A17: 3-5 | B17: between(HL6,3,5) | K17: 100
A18: 6-10 | B18: between(HL6,6,10) | K18: 100
A19: 11-14 | B19: between(HL6,11,14) | K19: 100
A20: 15-17 | B20: between(HL6,15,17) | K20: 100
A21: 18-34 | B21: between(HL6,18,34) | K21: 100
A22: 35-64 | B22: between(HL6,35,64) | K22: 100
A23: 65-84 | B23: between(HL6,65,84) | K23: 100
A24: 85+ | B24: between(HL6,85,95) | K24: 100
A25: Mother tongue / native language of household head
A26: Wolof | B26: headlang == 1 | K26: 100
A27: Poular | B27: headlang == 2 | K27: 100
A28: Serer | B28: headlang == 3 | K28: 100
A29: Diola | B29: headlang == 4 | K29: 100
A30: Other / Missing | B30: headlang == 6 | K30: 100
A31: Ethnicity of household head
A32: Wolof | B32: headethnic == 1 | K32: 100
A33: Poular | B33: headethnic == 2 | K33: 100
A34: Serer | B34: headethnic == 3 | K34: 100
A35: Diola | B35: headethnic == 4 | K35: 100
A36: Other / Missing | B36: headethnic == 6 | K36: 100
A37: Religion of household head
A38: Muslim | B38: headrelig == 1 | K38: 100
A39: Christian | B39: headrelig == 2 | K39: 100
A40: Other religion / No religion / Missing | B40: headrelig == 6 | K40: 100
A41: Wealth index quintile
A42: Poorest | B42: windex5 == 1 | K42: 100
...

Sheet 3.2
A1: Table 3.2 Formal education of household members age 3-24 years | P1: IDX
A2: Percentage of household members age 3-24 years who ever attended formal school or early childhood education (ECE) programme, percentage who are currently attending, and percent distribution by level of formal education currently attending, Senegal MICS Plus 2026, Wave 1
C3: Percentage who ever attended formal school or ECE programme | D3: Percentage who are currently attending formal school or ECE programme | E3: Number of household members age 3-24 years | G3: Percent distribution by level of formal education currently attending | M3: Total | N3: Number of household members age 3-24 years who are currently attending formal school or ECE programme
G4: Pre-primary or none | H4: Primary | I4: Lower secondary (Moyen) | J4: Upper secondary (Secondaire / Lycée) | K4: Higher education | L4: DK / Missing
B5: hl.sav filter(HL7 %in% c(1,NA) & between(HL6,3,24)) weight by hhweightA | C5: ED4 == 1 | D5: ED9 == 1 | E5: total == 1 | F5: total == 1 | G5: filter(ED9 == 1) - - - ED10A == 0 | H5: ED10A == 1 | I5: ED10A == 2 | J5: ED10A == 3 | K5: ED10A == 4 | L5: ED9 == 9 | ED10A >= 8 | M5: 100 | N5: total1 == 1 | O5: total1 == 1
A7: Total | B7: total == 1 | C7: p | E7: n | F7: n_unw | G7: p | M7: 100 | N7: n | O7: n_unw
A9: Area
A10: Urban | B10: area == 1 | M10: 100
A11: Rural | B11: area == 2 | M11: 100
A12: Sex
A13: Male | B13: HL4 == 1 | M13: 100
A14: Female | B14: HL4 == 2 | M14: 100
A15: Age
A16: 3-5 | B16: between(HL6,3,5) | M16: 100
A17: 6-11 | B17: between(HL6,6,11) | M17: 100
A18: 12-14 | B18: between(HL6,12,14) | M18: 100
A19: 15-17 | B19: between(HL6,15,17) | M19: 100
A20: 18-24 | B20: between(HL6,18,24) | M20: 100
A21: Education of household head
A22: Pre-primary or none | B22: headed == 0 | M22: 100
A23: Primary | B23: headed == 1 | M23: 100
A24: Lower secondary (Moyen) | B24: headed == 2 | M24: 100
A25: Upper secondary (Secondaire / Lycée) | B25: headed == 3 | M25: 100
A26: Higher education | B26: headed == 4 | M26: 100
A27: DK / Missing | B27: headed == 8 | M27: 100
A28: Mother tongue / native language of household head
A29: Wolof | B29: headlang == 1 | M29: 100
A30: Poular | B30: headlang == 2 | M30: 100
A31: Serer | B31: headlang == 3 | M31: 100
A32: Diola | B32: headlang == 4 | M32: 100
A33: Other / Missing | B33: headlang == 6 | M33: 100
A34: Ethnicity of household head
A35: Wolof | B35: headethnic == 1 | M35: 100
A36: Poular | B36: headethnic == 2 | M36: 100
A37: Serer | B37: headethnic == 3 | M37: 100
A38: Diola | B38: headethnic == 4 | M38: 100
A39: Other / Missing | B39: headethnic == 6 | M39: 100
A40: Religion of household head
A41: Muslim | B41: headrelig == 1 | M41: 100
A42: Christian | B42: headrelig == 2 | M42: 100
...

Sheet 3.3
A1: Table 3.3 Non-formal education of household members age 6 years or above | O1: IDX
A2: Percentage of household members age 6 years or above who attended any non-formal education since October 2025 among who ever attended non-formal education, and percentage by type of non-formal school attended since October 2025, Senegal MICS Plus 2026, Wave 1
C3: Percentage who attended any non-formal education since October 2025 | D3: Number of household members age 6 years or above who ever attended non-formal education | G3: Percentage by type of non-formal school attended since October 2025 | M3: Number of household members age 3 years or above who attended any non-formal education since October 2025
G4: Traditional Daara | H4: Qur'anic / Madrasa / Islamic school | I4: Trade / Craft apprenticeship | J4: Basic education / Literacy course | K4: Other | L4: DK / Missing
B5: hl.sav filter(HL7 %in% c(1,NA) & between(HL6,6,95) & ED4A == 1) weight by hhweightA | C5: NF6 == 1 | D5: total == 1 | E5: total == 1 | G5: filter(NF6 == 1) - - - NF7A == "A" | H5: NF7B == "B" | I5: NF7C == "C" | J5: NF7D == "D" | K5: NF7X == "X" | L5: NF7Z == "Z" | NF7NR == "?" | M5: total1 == 1 | N5: total1 == 1
A7: Total | B7: total == 1 | C7: p | D7: n | E7: n_unw | G7: p | M7: n | N7: n_unw
A9: Area
A10: Urban | B10: area == 1
A11: Rural | B11: area == 2
A12: Sex
A13: Male | B13: HL4 == 1
A14: Female | B14: HL4 == 2
A15: Age
A16: 6-10 | B16: between(HL6,6,10)
A17: 11-14 | B17: between(HL6,11,14)
A18: 15-17 | B18: between(HL6,15,17)
A19: 18-34 | B19: between(HL6,18,34)
A20: 35-64 | B20: between(HL6,35,64)
A21: 65-84 | B21: between(HL6,65,84)
A22: 85+ | B22: between(HL6,85,95)
A23: Education of household head
A24: Pre-primary or none | B24: headed == 0
A25: Primary | B25: headed == 1
A26: Lower secondary (Moyen) | B26: headed == 2
A27: Upper secondary (Secondaire / Lycée) | B27: headed == 3
A28: Higher education | B28: headed == 4
A29: DK / Missing | B29: headed == 8
A30: Mother tongue / native language of household head
A31: Wolof | B31: headlang == 1
A32: Poular | B32: headlang == 2
A33: Serer | B33: headlang == 3
A34: Diola | B34: headlang == 4
A35: Other / Missing | B35: headlang == 6
A36: Ethnicity of household head
A37: Wolof | B37: headethnic == 1
A38: Poular | B38: headethnic == 2
A39: Serer | B39: headethnic == 3
A40: Diola | B40: headethnic == 4
A41: Other / Missing | B41: headethnic == 6
A42: Religion of household head
...

Sheet 4.1
A1: Table 4.1 Food Insecurity Experience Scale (FIES)
A2: Percentage of household members experiencing moderate to severe food insecurity, based on the Food Insecurity Experience Scale, Senegal MICS Plus, 2026, Wave 1
B3: Percentage experiencing food insecurity | D3: Percentage experiencing moderate to severe food insecurity | E3: Number of household membersA
B4: Moderate food insecurity | C4: Severe food insecurity
A6: Total
A8: Area
A9: Urban
A10: Rural
A11: Sex of household head
A12: Male
A13: Female
A14: Age of household head
A15: 18-34
A16: 35-64
A17: 65-84
A18: 85+
... A48: A The FIES prevalence rates are calculated on the data from the households with no missing info on the FIES items. Hence, it is number of household members in such households.

Sheet 5.1
A1: Table 5.1 Child discipline | J1: IDX
A2: Percentage of children age 1-14 years, by child disciplining methods experienced during the past month, Senegal MICS Plus 2026, Wave 1
C3: Percentage who experienced | H3: Number of children age 1-14 years
C4: Only non-violent discipline | D4: Psychological aggression | E4: Physical punishment | G4: Any violent discipline method
E5: Any | F5: SevereA
B6: hh.sav filter(HH17 %in% c(0,1) & between(RS2B,1,14)) weight by ch117weightA | C6: (CD1A == 1 | CD1B == 1 | CD1E == 1) & (CD1C != 1 & CD1D != 1 & CD1F != 1 & CD1G != 1 & CD1H != 1 & CD1I != 1 & CD1J != 1 & CD1K != 1) | D6: CD1D == 1 | CD1H == 1 | E6: CD1C == 1 | CD1F == 1 | CD1G == 1 | CD1I == 1 | CD1J == 1 | CD1K == 1 | F6: CD1I == 1 | CD1K == 1 | G6: CD1C == 1 | CD1D == 1 | CD1F == 1 | CD1G == 1 | CD1H == 1 | CD1I == 1 | CD1J == 1 | CD1K == 1 | H6: total == 1 | I6: total == 1
A8: Total | B8: total == 1 | C8: p | H8: n | I8: n_unw
A10: Area
A11: Urban | B11: area == 1
A12: Rural | B12: area == 2
A13: Sex
A14: Male | B14: ch117sex == 1
A15: Female | B15: ch117sex == 2
A16: Age
A17: 1-2 | B17: between(ch117age,1,2)
A18: 3-4 | B18: between(ch117age,3,4)
A19: 5-9 | B19: between(ch117age,5,9)
A20: 10-14 | B20: between(ch117age,10,14)
A21: Education of household head
A22: Pre-primary or none | B22: headed == 0
A23: Primary | B23: headed == 1
A24: Lower secondary (Moyen) | B24: headed == 2
A25: Upper secondary (Secondaire / Lycée) | B25: headed == 3
A26: Higher education | B26: headed == 4
A27: DK / Missing | B27: headed == 8
A28: Mother tongue / native language of household head
A29: Wolof | B29: headlang == 1
A30: Poular | B30: headlang == 2
A31: Serer | B31: headlang == 3
A32: Diola | B32: headlang == 4
A33: Other / Missing | B33: headlang == 6
A34: Ethnicity of household head
A35: Wolof | B35: headethnic == 1
A36: Poular | B36: headethnic == 2
A37: Serer | B37: headethnic == 3
A38: Diola | B38: headethnic == 4
A39: Other / Missing | B39: headethnic == 6
A40: Religion of household head
A41: Muslim | B41: headrelig == 1
A42: Christian | B42: headrelig == 2
...

Sheet 5.2
A1: Table 5.2 Attitudes toward physical punishment | F1: IDX
A2: Percentage of respondentsA of households with at least one child age 1-14 years who believe that physical punishment is needed to bring up, raise, or educate a child properly, Senegal MICS Plus 2026, Wave 1
C3: Percentage who believe that a child needs to be physically punished | D3: Number of respondents of households with at least one child age 1-14 years
B4: hh.sav filter(HH17 %in% c(0,1) & between(RS2B,1,14)) weight by hhweightA | C4: CD2 == 1 | D4: total == 1 | E4: total == 1
A6: Total | B6: total == 1 | C6: p | D6: n | E6: n_unw
A8: Area
A9: Urban | B9: area == 1
A10: Rural | B10: area == 2
A11: Sex
A12: Male | B12: respsex == 1
A13: Female | B13: respsex == 2
A14: Age
A15: <18 | B15: respage < 18
A16: 18-34 | B16: between(respage,18,34)
A17: 35-64 | B17: between(respage,35,64)
A18: 65-84 | B18: between(respage,65,84)
A19: 85+ | B19: between(respage,85,95)
A20: Education of household head
A21: Pre-primary or none | B21: headed == 0
A22: Primary | B22: headed == 1
A23: Lower secondary (Moyen) | B23: headed == 2
A24: Upper secondary (Secondaire / Lycée) | B24: headed == 3
A25: Higher education | B25: headed == 4
A26: DK / Missing | B26: headed == 8
A27: Mother tongue / native language of household head
A28: Wolof | B28: headlang == 1
A29: Poular | B29: headlang == 2
A30: Serer | B30: headlang == 3
A31: Diola | B31: headlang == 4
A32: Other / Missing | B32: headlang == 6
A33: Ethnicity of household head
A34: Wolof | B34: headethnic == 1
A35: Poular | B35: headethnic == 2
A36: Serer | B36: headethnic == 3
A37: Diola | B37: headethnic == 4
A38: Other / Missing | B38: headethnic == 6
A39: Religion of household head
A40: Muslim | B40: headrelig == 1
A41: Christian | B41: headrelig == 2
A42: Other religion / No religion / Missing | B42: headrelig == 6
...

Sheet 6.1
A1: Table 6.1 Children's involvement in economic activities | N1: IDX
A2: Percentage of children age 5-17 years by involvement in economic activities during the last 7 days and age groups, Senegal MICS Plus 2026, Wave 1
C3: Percentage involved in economic activity for at least one hour | D3: Number of children age 5-11 years | F3: Percentage involved in: | H3: Number of children age 12-14 years | J3: Percentage involved in: | L3: Number of children age 15-17 years
F4: Economic activity less than 14 hours | G4: Economic activity for 14 hours or more | J4: Economic activity less than 43 hours | K4: Economic activity for 43 hours or more
B5: hh.sav filter(HH17 %in% c(0,1) & between(RS2B,5,17)) weight by ch117weightA | C5: filter(between(RS2B, 5, 11)) - - - define(ea) define(ea1more) - - - ea1more == 1 | D5: total == 1 | E5: total == 1 | F5: filter(between(RS2B, 12, 14)) - - - define(ea14less) - - - ea14less == 1 | G5: ea == 1 & CL3 >= 14 & CL3 < 97 | H5: total == 1 | I5: total == 1 | J5: filter(between(RS2B, 15, 17)) - - - ea == 1 & CL3 < 43 | K5: ea == 1 & CL3 >= 43 & CL3 < 97 | L5: total == 1 | M5: total == 1
A7: Total | B7: total == 1 | C7: p | D7: n | E7: n_unw | F7: p | H7: n | I7: n_unw | J7: p | L7: n | M7: n_unw
A9: Area
A10: Urban | B10: area == 1
A11: Rural | B11: area == 2
A12: Sex
A13: Male | B13: ch117sex == 1
A14: Female | B14: ch117sex == 2
A15: School attendance
A16: Attending | B16: ED9 == 1
A17: Not attending | B17: ED4 == 2 | ED9 == 2
A18: Missing | B18: ED9 == 9
A19: Education of household head
A20: Pre-primary or none | B20: headed == 0
A21: Primary | B21: headed == 1
A22: Lower secondary (Moyen) | B22: headed == 2
A23: Upper secondary (Secondaire / Lycée) | B23: headed == 3
A24: Higher education | B24: headed == 4
A25: DK / Missing | B25: headed == 8
A26: Mother tongue / native language of household head
A27: Wolof | B27: headlang == 1
A28: Poular | B28: headlang == 2
A29: Serer | B29: headlang == 3
A30: Diola | B30: headlang == 4
A31: Other / Missing | B31: headlang == 6
A32: Ethnicity of household head
A33: Wolof | B33: headethnic == 1
A34: Poular | B34: headethnic == 2
A35: Serer | B35: headethnic == 3
A36: Diola | B36: headethnic == 4
A37: Other / Missing | B37: headethnic == 6
A38: Religion of household head
A39: Muslim | B39: headrelig == 1
A40: Christian | B40: headrelig == 2
A41: Other religion / No religion / Missing | B41: headrelig == 6
A42: Wealth index quintile
...

Sheet 6.2
A1: Table 6.2 Children's involvement in household chores | K1: IDX
A2: Percentage of children age 5-14 years, by involvement in household choresA during the last 7 days and age groups, Senegal MICS Plus 2026, Wave 1
C3: Percentage involved in: | E3: Number of children age 5-11 years | G3: Percentage involved in: | I3: Number of children age 12-14 years
C4: Household chores less than 21 hours | D4: Household chores for 21 hours or more | G4: Household chores less than 21 hours | H4: Household chores for 21 hours or more
B5: hh.sav filter(HH17 %in% c(0,1) & between(RS2B,5,14)) define(hhc) define(CL8_CL10_CL13) define(hhc21less) define(hhc21more) weight by ch117weightA | C5: filter(between(RS2B, 5, 11)) - - - hhc21less == 1 | D5: hhc21more == 1 | E5: total == 1 | F5: total == 1 | G5: filter(between(RS2B, 12, 14)) - - - hhc21less == 1 | H5: hhc21more == 1 | I5: total == 1 | J5: total == 1
A7: Total | B7: total == 1 | C7: p | E7: n | F7: n_unw | G7: p | I7: n | J7: n_unw
A9: Area
A10: Urban | B10: area == 1
A11: Rural | B11: area == 2
A12: Sex
A13: Male | B13: ch117sex == 1
A14: Female | B14: ch117sex == 2
A15: School attendance
A16: Attending | B16: ED9 == 1
A17: Not attending | B17: ED4 == 2 | ED9 == 2
A18: Missing | B18: ED9 == 9
A19: Education of household head
A20: Pre-primary or none | B20: headed == 0
A21: Primary | B21: headed == 1
A22: Lower secondary (Moyen) | B22: headed == 2
A23: Upper secondary (Secondaire / Lycée) | B23: headed == 3
A24: Higher education | B24: headed == 4
A25: DK / Missing | B25: headed == 8
A26: Mother tongue / native language of household head
A27: Wolof | B27: headlang == 1
A28: Poular | B28: headlang == 2
A29: Serer | B29: headlang == 3
A30: Diola | B30: headlang == 4
A31: Other / Missing | B31: headlang == 6
A32: Ethnicity of household head
A33: Wolof | B33: headethnic == 1
A34: Poular | B34: headethnic == 2
A35: Serer | B35: headethnic == 3
A36: Diola | B36: headethnic == 4
A37: Other / Missing | B37: headethnic == 6
A38: Religion of household head
A39: Muslim | B39: headrelig == 1
A40: Christian | B40: headrelig == 2
A41: Other religion / No religion / Missing | B41: headrelig == 6
A42: Wealth index quintile
...

Sheet 6.3
A1: Table 6.3 Child labour | K1: IDX
A2: Percentage of children age 5-17 years by involvement in economic activities or household chores during the last 7 days and percentage engaged in child labour during the last 7 days, Senegal MICS Plus 2026, Wave 1
C3: Percentage involved in economic activities for a total number of hours during the last 7 days: | F3: Percentage involved in household chores for a total number of hours during the last 7 days: | H3: Total child labourA | I3: Number of children age 5-17 years
C4: Below the age specific threshold | D4: At or above the age specific threshold | F4: Below the age specific threshold | G4: At or above the age specific threshold
B5: hh.sav filter(HH17 %in% c(0,1) & between(RS2B,5,17)) define(ea) define(hhc) define(CL8_CL10_CL13) define(hhc21less) define(hhc21more) weight by ch117weightA | C5: mutate(ea1less = case_when( between(RS2B, 5, 11) ~ if_else( ea == 1 & CL3 < 1, 1, 0, missing = 0 ), TRUE ~ NA_real_ )) mutate(ea14less = case_when( between(RS2B, 12, 14) ~ if_else( ea == 1 & CL3 < 14, 1, 0, missing = 0 ), TRUE ~ NA_real_ )) mutate(ea43less = case_when( between(RS2B, 15, 17) ~ if_else( ea == 1 & CL3 < 43, 1, 0, missing = 0 ), TRUE ~ NA_real_ )) - - - ea1less %in% c(1) | ea14less %in% c(1) | ea43less %in% c(1) | D5: mutate(ea1more = case_when( between(RS2B, 5, 11) ~ if_else( ea == 1 & CL3 >= 1 & CL3 < 97, 1, 0, missing = 0 ), TRUE ~ NA_real_ )) mutate(ea14more = case_when( between(RS2B, 12, 14) ~ if_else( ea == 1 & CL3 >= 14 & CL3 < 97, 1, 0, missing = 0 ), TRUE ~ NA_real_ )) mutate(ea43more = case_when( between(RS2B, 15, 17) ~ if_else( ea == 1 & CL3 >= 43 & CL3 < 97, 1, 0, missing = 0 ), TRUE ~ NA_real_ )) - - - ea1more %in% c(1) | ea14more %in% c(1) | ea43more %in% c(1) | F5: between(RS2B, 5, 14) & hhc21less %in% c(1) | G5: between(RS2B, 5, 14) & hhc21more %in% c(1) | H5: ea1more %in% c(1) | ea14more %in% c(1) | ea43more %in% c(1) | (between(RS2B, 5, 14) & hhc21more %in% c(1)) | I5: total == 1 | J5: total == 1
A7: Total | B7: total == 1 | C7: p | I7: n | J7: n_unw
A9: Area
A10: Urban | B10: area == 1
A11: Rural | B11: area == 2
A12: Sex
A13: Male | B13: ch117sex == 1
A14: Female | B14: ch117sex == 2
A15: Age
A16: 5-11 | B16: ch117age <= 11
A17: 12-14 | B17: between(ch117age,12,14)
A18: 15-17 | B18: ch117age >= 15
A19: School attendance
A20: Attending | B20: ED9 == 1
A21: Not attending | B21: ED4 == 2 | ED9 == 2
A22: Missing | B22: ED9 == 9
A23: Education of household head
A24: Pre-primary or none | B24: headed == 0
A25: Primary | B25: headed == 1
A26: Lower secondary (Moyen) | B26: headed == 2
A27: Upper secondary (Secondaire / Lycée) | B27: headed == 3
A28: Higher education | B28: headed == 4
A29: DK / Missing | B29: headed == 8
A30: Mother tongue / native language of household head
A31: Wolof | B31: headlang == 1
A32: Poular | B32: headlang == 2
A33: Serer | B33: headlang == 3
A34: Diola | B34: headlang == 4
A35: Other / Missing | B35: headlang == 6
A36: Ethnicity of household head
A37: Wolof | B37: headethnic == 1
A38: Poular | B38: headethnic == 2
A39: Serer | B39: headethnic == 3
A40: Diola | B40: headethnic == 4
A41: Other / Missing | B41: headethnic == 6
A42: Religion of household head
...

Sheet 6.4
A1: Table 6.4 Hazardous work | R1: IDX
A2: Percentage of children age 5-17 years involved in economic activities or household chores at or above the age specific thresholds, percentage working under hazardous conditions, by type of work, and percentage involved in economic activities or household chores at or above thresholds or working under hazardous conditions during the last 7 days, Senegal MICS Plus 2026, Wave 1
C3: Percentage involved in: | F3: Percentage working under hazardous conditions | O3: Percentage involved in economic activities or household chores at or above thresholds, or working under hazardous conditionsA | P3: Number of children age 5-17 years
C4: Economic activities at or above age specific threshold | D4: Household chores at or above age specific threshold | F4: Carrying heavy loads | G4: Working with dangerous tools or operating heavy machinery | H4: Exposed to dust, fumes or gas | I4: Exposed to extreme cold, heat or humidity | J4: Exposed to loud noise or vibration | K4: Working at heights | L4: Working with chemicals or explosives | M4: Exposed to other unsafe or unhealthy things, processes or conditions | N4: Total hazardous work
B6: hh.sav filter(HH17 %in% c(0,1) & between(RS2B,5,17)) define(ea) define(hhc) define(CL8_CL10_CL13) define(hhc21more) weight by ch117weightA | C6: mutate(ea1more = case_when( between(RS2B, 5, 11) ~ if_else( ea == 1 & CL3 >= 1 & CL3 < 97, 1, 0, missing = 0 ), TRUE ~ NA_real_ )) mutate(ea14more = case_when( between(RS2B, 12, 14) ~ if_else( ea == 1 & CL3 >= 14 & CL3 < 97, 1, 0, missing = 0 ), TRUE ~ NA_real_ )) mutate(ea43more = case_when( between(RS2B, 15, 17) ~ if_else( ea == 1 & CL3 >= 43 & CL3 < 97, 1, 0, missing = 0 ), TRUE ~ NA_real_ )) - - - ea1more %in% c(1) | ea14more %in% c(1) | ea43more %in% c(1) | D6: between(RS2B, 5, 14) & hhc21more %in% c(1) | F6: CL4 == 1 | G6: CL5 == 1 | H6: CL6A == 1 | I6: CL6B == 1 | J6: CL6C == 1 | K6: CL6D == 1 | L6: CL6E == 1 | M6: CL6X == 1 | N6: mutate(tothaz = if_else( CL4 == 1 | CL5 == 1 | CL6A == 1 | CL6B == 1 | CL6C == 1 | CL6D == 1 | CL6E == 1 | CL6X == 1, 1, 0, missing = 0 )) - - - tothaz %in% c(1) | O6: ea1more %in% c(1) | ea14more %in% c(1) | ea43more %in% c(1) | (between(RS2B, 5, 14) & hhc21more %in% c(1)) | tothaz %in% c(1) | P6: total == 1 | Q6: total == 1
A8: Total | B8: total == 1 | C8: p | P8: n | Q8: n_unw
A10: Area
A11: Urban | B11: area == 1
A12: Rural | B12: area == 2
A13: Sex
A14: Male | B14: ch117sex == 1
A15: Female | B15: ch117sex == 2
A16: Age
A17: 5-11 | B17: ch117age <= 11
A18: 12-14 | B18: between(ch117age,12,14)
A19: 15-17 | B19: ch117age >= 15
A20: School attendance
A21: Attending | B21: ED9 == 1
A22: Not attending | B22: ED4 == 2 | ED9 == 2
A23: Missing | B23: ED9 == 9
A24: Education of household head
A25: Pre-primary or none | B25: headed == 0
A26: Primary | B26: headed == 1
A27: Lower secondary (Moyen) | B27: headed == 2
A28: Upper secondary (Secondaire / Lycée) | B28: headed == 3
A29: Higher education | B29: headed == 4
A30: DK / Missing | B30: headed == 8
A31: Mother tongue / native language of household head
A32: Wolof | B32: headlang == 1
A33: Poular | B33: headlang == 2
A34: Serer | B34: headlang == 3
A35: Diola | B35: headlang == 4
A36: Other / Missing | B36: headlang == 6
A37: Ethnicity of household head
A38: Wolof | B38: headethnic == 1
A39: Poular | B39: headethnic == 2
A40: Serer | B40: headethnic == 3
A41: Diola | B41: headethnic == 4
A42: Other / Missing | B42: headethnic == 6
A43: Religion of household head
...

Sheet 7.1
A1: Table 7.1 Use of improved and unimproved water sources | Z1: IDX
A2: Percent distribution of household members by main source of drinking water and percentage using improved drinking water sources, Senegal MICS Plus 2025-26, Wave 1
C3: Percent distribution of household members by main source of drinking water | V3: Total | W3: Percentage of household members using improved sources of drinking water | X3: Number of household members
C4: Improved sources | R4: Unimproved sources
C5: Piped water | G5: Tube well / Borehole | H5: Protected well | I5: Protected spring | J5: Rainwater | K5: Tanker-truck | N5: Bottled water | P5: Large bottle / Dispenser refill | R5: Unprotected well | S5: Unprotected spring | T5: Surface water | U5: Other
C6: Into dwelling | D6: To yard / plot | E6: To neighbour | F6: To public tap / standpipe | L6: Cart with small tank | M6: Water kiosk | O6: Sachet water
B7: hh.sav mutate(hhmemwt = hhweightA*HLnum) filter(HH17 %in% c(0,1)) weight by hhmemwt | C7: WS1 == 11 | D7: WS1 == 12 | E7: WS1 == 13 | F7: WS1 == 14 | G7: WS1 == 21 | H7: WS1 == 31 | I7: WS1 == 41 | J7: WS1 == 51 | K7: WS1 == 61 | L7: WS1 == 71 | M7: WS1 == 72 | N7: WS1 == 91 | O7: WS1 == 92 | P7: WS1 == 93 | R7: WS1 == 32 | S7: WS1 == 42 | T7: WS1 == 81 | U7: WS1 == 96 | V7: 100 | W7: WS1 %in% c(11,12,13,14,21,31,41,51,61,71,72,91,92,93) | X7: total == 1 | Y7: totalHL == 1
A9: Total | B9: total == 1 | C9: p | V9: 100 | W9: p | X9: n | Y9: n_unw
A11: Area
A12: Urban | B12: area == 1 | V12: 100
A13: Rural | B13: area == 2 | V13: 100
A14: Education of household head
A15: Pre-primary or none | B15: headed == 0 | V15: 100
A16: Primary | B16: headed == 1 | V16: 100
A17: Lower secondary (Moyen) | B17: headed == 2 | V17: 100
A18: Upper secondary (Secondaire / Lycée) | B18: headed == 3 | V18: 100
A19: Higher education | B19: headed == 4 | V19: 100
A20: DK / Missing | B20: headed == 8 | V20: 100
A21: Mother tongue / native language of household head
A22: Wolof | B22: headlang == 1 | V22: 100
A23: Poular | B23: headlang == 2 | V23: 100
A24: Serer | B24: headlang == 3 | V24: 100
A25: Diola | B25: headlang == 4 | V25: 100
A26: Other / Missing | B26: headlang == 6 | V26: 100
A27: Ethnicity of household head
A28: Wolof | B28: headethnic == 1 | V28: 100
A29: Poular | B29: headethnic == 2 | V29: 100
A30: Serer | B30: headethnic == 3 | V30: 100
A31: Diola | B31: headethnic == 4 | V31: 100
A32: Other / Missing | B32: headethnic == 6 | V32: 100
A33: Religion of household head
A34: Muslim | B34: headrelig == 1 | V34: 100
A35: Christian | B35: headrelig == 2 | V35: 100
A36: Other religion / No religion / Missing | B36: headrelig == 6 | V36: 100
A37: Wealth index quintile
A38: Poorest | B38: windex5 == 1 | V38: 100
A39: Second | B39: windex5 == 2 | V39: 100
A40: Middle | B40: windex5 == 3 | V40: 100
A41: Fourth | B41: windex5 == 4 | V41: 100
A42: Richest | B42: windex5 == 5 | V42: 100

Sheet 7.2
A1: Table 7.2 Use of basic and limited drinking water services | P1: IDX
A2: Percent distribution of household members by time to go to the main source of drinking water, get water and return, for users of improved and unimproved drinking water sources and percentage using basic drinking water services, Senegal MICS Plus 2025-26, Wave 1
C3: Percent distribution of household members by time to the main source of drinking water | L3: Total | M3: Percentage of household members using basic drinking water services | N3: Number of household members
C4: Improved sources | H4: Unimproved sources
C5: Water on premisesA | D5: Up to and including 30 minutes A | E5: More than 30 minutes | F5: DK / Missing | H5: Water on premisesA | I5: Up to and including 30 minutesB | J5: More than 30 minutes | K5: DK / Missing
B6: hh.sav mutate(hhmemwt = hhweightA*HLnum) filter(HH17 %in% c(0,1)) weight by hhmemwt | C6: mutate(WS1R = if_else(WS1 %in% c(11,12,13,14,21,31,41,51,61,71,72,91,92,93) ,1,0)) - - - WS1R == 1 & (WS1 %in% c(11,12) | WS3 %in% c(1,2) | WS4 == 0) | D6: WS1R == 1 & between(WS4,1,30) | E6: WS1R == 1 & between(WS4,31,990) | F6: WS1R == 1 & between(WS4,998,999) | H6: mutate(WS1R = if_else(WS1 %in% c(32,42,81,96) ,1,0)) - - - WS1R == 1 & (WS3 %in% c(1,2) | WS4 == 0) | I6: WS1R == 1 & between(WS4,1,30) | J6: WS1R == 1 & between(WS4,31,990) | K6: WS1R == 1 & between(WS4,998,999) | L6: 100 | M6: WS1 %in% c(11,12,13,14,21,31,41,51,61,71,72,91,92,93) & (WS1 %in% c(11,12) | WS3 %in% c(1,2) | WS4 < 31) | N6: total == 1 | O6: totalHL == 1
A8: Total | B8: total == 1 | C8: p | L8: 100 | M8: p | N8: n | O8: n_unw
A10: Area
A11: Urban | B11: area == 1 | L11: 100
A12: Rural | B12: area == 2 | L12: 100
A13: Education of household head
A14: Pre-primary or none | B14: headed == 0 | L14: 100
A15: Primary | B15: headed == 1 | L15: 100
A16: Lower secondary (Moyen) | B16: headed == 2 | L16: 100
A17: Upper secondary (Secondaire / Lycée) | B17: headed == 3 | L17: 100
A18: Higher education | B18: headed == 4 | L18: 100
A19: DK / Missing | B19: headed == 8 | L19: 100
A20: Mother tongue / native language of household head
A21: Wolof | B21: headlang == 1 | L21: 100
A22: Poular | B22: headlang == 2 | L22: 100
A23: Serer | B23: headlang == 3 | L23: 100
A24: Diola | B24: headlang == 4 | L24: 100
A25: Other / Missing | B25: headlang == 6 | L25: 100
A26: Ethnicity of household head
A27: Wolof | B27: headethnic == 1 | L27: 100
A28: Poular | B28: headethnic == 2 | L28: 100
A29: Serer | B29: headethnic == 3 | L29: 100
A30: Diola | B30: headethnic == 4 | L30: 100
A31: Other / Missing | B31: headethnic == 6 | L31: 100
A32: Religion of household head
A33: Muslim | B33: headrelig == 1 | L33: 100
A34: Christian | B34: headrelig == 2 | L34: 100
A35: Other religion / No religion / Missing | B35: headrelig == 6 | L35: 100
A36: Wealth index quintile
A37: Poorest | B37: windex5 == 1 | L37: 100
A38: Second | B38: windex5 == 2 | L38: 100
A39: Middle | B39: windex5 == 3 | L39: 100
A40: Fourth | B40: windex5 == 4 | L40: 100
A41: Richest | B41: windex5 == 5 | L41: 100
A42: A Water on premises are water sources that are either 1) water piped into dwelling, yard, or plot, or 2) water from other sources reported to be located in the dwelling yard or plot, or where household members do not collect water. This excludes piped to neighbour and public tap/standpipe, which by definition are off-premises. The MICS Plus module on drinking water sources does not contain the same number of questions as in MICS, and the findings are not directly comparable.
...

Sheet 7.3
A1: Table 7.3 Availability of sufficient drinking water when needed | O1: IDX
A2: Percentage of household members who did not have sufficient drinking water when needed in the last 7 days and percent distribution by main reason for not having sufficient drinking water in the last 7 days, Senegal MICS Plus 2025-26, Wave 1
C3: Percentage who did not have sufficient drinking water when needed in the last 7 days | D3: Number of household members | F3: Percent distribution by main reason for not having sufficient drinking water in the last 7 days | L3: Total | M3: Number of household members who did not have sufficient drinking water when needed in the last 7 days
F4: Water source not functional | G4: Water source not accessible | H4: Water not available | I4: Water too expensive | J4: Other | K4: DK / Missing
B5: hh.sav mutate(hhmemwt = hhweightA*HLnum) filter(HH17 %in% c(0,1)) weight by hhmemwt | C5: WS7 == 1 | D5: total == 1 | E5: totalHL == 1 | F5: filter(WS7 == 1) - - - WS8 == 1 | G5: WS8 == 2 | H5: WS8 == 3 | I5: WS8 == 4 | J5: WS8 == 6 | K5: WS8 >= 8 | L5: 100 | M5: total1 == 1 | N5: totalHL1 == 1
A7: Total | B7: total == 1 | C7: p | D7: n | E7: n_unw | L7: 100 | M7: n | N7: n_unw
A9: Area
A10: Urban | B10: area == 1 | L10: 100
A11: Rural | B11: area == 2 | L11: 100
A12: Education of household head
A13: Pre-primary or none | B13: headed == 0 | L13: 100
A14: Primary | B14: headed == 1 | L14: 100
A15: Lower secondary (Moyen) | B15: headed == 2 | L15: 100
A16: Upper secondary (Secondaire / Lycée) | B16: headed == 3 | L16: 100
A17: Higher education | B17: headed == 4 | L17: 100
A18: DK / Missing | B18: headed == 8 | L18: 100
A19: Mother tongue / native language of household head
A20: Wolof | B20: headlang == 1 | L20: 100
A21: Poular | B21: headlang == 2 | L21: 100
A22: Serer | B22: headlang == 3 | L22: 100
A23: Diola | B23: headlang == 4 | L23: 100
A24: Other / Missing | B24: headlang == 6 | L24: 100
A25: Ethnicity of household head
A26: Wolof | B26: headethnic == 1 | L26: 100
A27: Poular | B27: headethnic == 2 | L27: 100
A28: Serer | B28: headethnic == 3 | L28: 100
A29: Diola | B29: headethnic == 4 | L29: 100
A30: Other / Missing | B30: headethnic == 6 | L30: 100
A31: Religion of household head
A32: Muslim | B32: headrelig == 1 | L32: 100
A33: Christian | B33: headrelig == 2 | L33: 100
A34: Other religion / No religion / Missing | B34: headrelig == 6 | L34: 100
A35: Wealth index quintile | L35: 100
A36: Poorest | B36: windex5 == 1 | L36: 100
A37: Second | B37: windex5 == 2 | L37: 100
A38: Middle | B38: windex5 == 3 | L38: 100
A39: Fourth | B39: windex5 == 4 | L39: 100
A40: Richest | B40: windex5 == 5

Sheet 7.4
A1: Table 7.4 Use of improved and unimproved sanitation facilities | Y1: IDX
A2: Percent distribution of household members by type of sanitation facility used by household and percentage using improved sanitation facilities, Senegal MICS Plus 2025-26, Wave 1
C3: Percent distibution of household members by type of sanitation facility used by household | S3: Open defecation (no facility, bush, field) | T3: Missing | U3: Total | V3: Percentage using improved sanitation facilities | W3: Number of household members
C4: Improved sanitation facility | N4: Unimproved sanitation facility
C5: Flush / Pour flush to: | H5: Pit latrine with slab | K5: Composting toilet | L5: Container based sanitation | N5: Flush / Pour flush to open drain | O5: Pit latrine without slab / open pit | P5: Bucket | Q5: Hanging toilet / Hanging latrine | R5: Other
C6: Piped sewer system | D6: Septic tank | E6: Pit latrine | F6: DK where | H6: Ventilated improved (VIP) | I6: Single | J6: Twin
B7: hh.sav mutate(hhmemwt = hhweightA*HLnum) filter(HH17 %in% c(0,1)) weight by hhmemwt | C7: WS11 == 11 | D7: WS11 == 12 | E7: WS11 == 13 | F7: WS11 == 18 | H7: WS11 == 21 | I7: WS11 == 22 | J7: WS11 == 24 | K7: WS11 == 31 | L7: WS11 == 32 | N7: WS11 == 14 | O7: WS11 == 23 | P7: WS11 == 41 | Q7: WS11 == 51 | R7: WS11 == 96 | S7: WS11 == 95 | T7: WS11 == 99 | U7: 100 | V7: WS11 %in% c(11,12,13,18,21,22,24,31,32) | W7: total == 1 | X7: totalHL == 1
A9: Total | B9: total == 1 | C9: p | U9: 100 | V9: p | W9: n | X9: n_unw
A11: Area
A12: Urban | B12: area == 1 | U12: 100
A13: Rural | B13: area == 2 | U13: 100
A14: Education of household head
A15: Pre-primary or none | B15: headed == 0 | U15: 100
A16: Primary | B16: headed == 1 | U16: 100
A17: Lower secondary (Moyen) | B17: headed == 2 | U17: 100
A18: Upper secondary (Secondaire / Lycée) | B18: headed == 3 | U18: 100
A19: Higher education | B19: headed == 4 | U19: 100
A20: DK / Missing | B20: headed == 8 | U20: 100
A21: Mother tongue / native language of household head
A22: Wolof | B22: headlang == 1 | U22: 100
A23: Poular | B23: headlang == 2 | U23: 100
A24: Serer | B24: headlang == 3 | U24: 100
A25: Diola | B25: headlang == 4 | U25: 100
A26: Other / Missing | B26: headlang == 6 | U26: 100
A27: Ethnicity of household head
A28: Wolof | B28: headethnic == 1 | U28: 100
A29: Poular | B29: headethnic == 2 | U29: 100
A30: Serer | B30: headethnic == 3 | U30: 100
A31: Diola | B31: headethnic == 4 | U31: 100
A32: Other / Missing | B32: headethnic == 6 | U32: 100
A33: Religion of household head
A34: Muslim | B34: headrelig == 1 | U34: 100
A35: Christian | B35: headrelig == 2 | U35: 100
A36: Other religion / No religion / Missing | B36: headrelig == 6 | U36: 100
A37: Wealth index quintile
A38: Poorest | B38: windex5 == 1 | U38: 100
A39: Second | B39: windex5 == 2 | U39: 100
A40: Middle | B40: windex5 == 3 | U40: 100
A41: Fourth | B41: windex5 == 4 | U41: 100
A42: Richest | B42: windex5 == 5 | U42: 100

Sheet 7.5
A1: Table 7.5 Use of basic and limited sanitation services | U1: IDX
A2: Percent distribution of household members by use of private and public sanitation facilities and use of shared facilities by users of improved and unimproved sanitation facilities, Senegal MICS Plus 2025-26, Wave 1
C3: Percentage using improved sanitation facilities that are: | J3: Percentage using unimproved sanitation facilities that are: | P3: Open defecation (no facility, bush, field) | Q3: Missing | R3: Total | S3: Number of household members
C4: Not shared | D4: Shared with neighbors | G4: Public facility | H4: Missing | J4: Not shared | K4: Shared with neighbors | N4: Public facility | O4: Missing
D5: 5 households or less | E5: More than 5 households | F5: DK how many households | K5: 5 households or less | L5: More than 5 households | M5: DK how many households
B6: hh.sav mutate(hhmemwt = hhweightA*HLnum) filter(HH17 %in% c(0,1)) weight by hhmemwt | C6: mutate(WS11R = if_else(WS11 %in% c(11,12,13,18,21,22,24,31,32) ,1,0)) - - - WS11R == 1 & WS15 == 2 | D6: WS11R == 1 & WS17 <= 5 | E6: WS11R == 1 & between(WS17,6,10) | F6: WS11R == 1 & WS17 >= 98 | G6: WS11R == 1 & WS16 == 2 | H6: WS11R == 1 & (WS12 == 9 | WS14 == 9) | J6: mutate(WS11R = if_else(WS11 %in% c(14,23,41,51,96) ,1,0)) - - - WS11R == 1 & WS15 == 2 | K6: WS11R == 1 & WS17 <= 5 | L6: WS11R == 1 & between(WS17,6,10) | M6: WS11R == 1 & WS17 >= 98 | N6: WS11R == 1 & WS16 == 2 | O6: WS11R == 1 & (WS12 == 9 | WS14 == 9) | P6: WS11 == 95 | Q6: WS11 == 99 | R6: 100 | S6: total == 1 | T6: totalHL == 1
A8: Total | B8: total == 1 | C8: p | R8: 100 | S8: n | T8: n_unw
A10: Area
A11: Urban | B11: area == 1 | R11: 100
A12: Rural | B12: area == 2 | R12: 100
A13: Education of household head
A14: Pre-primary or none | B14: headed == 0 | R14: 100
A15: Primary | B15: headed == 1 | R15: 100
A16: Lower secondary (Moyen) | B16: headed == 2 | R16: 100
A17: Upper secondary (Secondaire / Lycée) | B17: headed == 3 | R17: 100
A18: Higher education | B18: headed == 4 | R18: 100
A19: DK / Missing | B19: headed == 8 | R19: 100
A20: Mother tongue / native language of household head
A21: Wolof | B21: headlang == 1 | R21: 100
A22: Poular | B22: headlang == 2 | R22: 100
A23: Serer | B23: headlang == 3 | R23: 100
A24: Diola | B24: headlang == 4 | R24: 100
A25: Other / Missing | B25: headlang == 6 | R25: 100
A26: Ethnicity of household head
A27: Wolof | B27: headethnic == 1 | R27: 100
A28: Poular | B28: headethnic == 2 | R28: 100
A29: Serer | B29: headethnic == 3 | R29: 100
A30: Diola | B30: headethnic == 4 | R30: 100
A31: Other / Missing | B31: headethnic == 6 | R31: 100
A32: Religion of household head
A33: Muslim | B33: headrelig == 1 | R33: 100
A34: Christian | B34: headrelig == 2 | R34: 100
A35: Other religion / No religion / Missing | B35: headrelig == 6 | R35: 100
A36: Wealth index quintile
A37: Poorest | B37: windex5 == 1 | R37: 100
A38: Second | B38: windex5 == 2 | R38: 100
A39: Middle | B39: windex5 == 3 | R39: 100
A40: Fourth | B40: windex5 == 4 | R40: 100
A41: Richest | B41: windex5 == 5 | R41: 100

Sheet 7.6
A1: Table 7.6 Handwashing facility and availability of water and soap to wash hands when needed | AE1: IDX
A2: Percent distribution of household members by type of handwashing facility, percentage who did not have sufficient water to wash hands when needed in the last 7 days and percent distribution by main reason for not having sufficient water, and percentage who did not have sufficient soap to wash hands when needed in the last 7 days and percent distribution by main reason for not having sufficient soap, Senegal MICS Plus 2025-26, Wave 1
C3: Percent distribution of household members by type of handwashing facility | E3: No handwashing place in in the dwelling, yard, or plot | F3: Other | G3: Missing | H3: Total | I3: Percentage who did not have sufficient water to wash hands when needed in the last 7 days | J3: Percentage who did not have sufficient soap to wash hands when needed in the last 7 days | K3: Number of household members | N3: Percent distribution by main reason for not having sufficient water to wash hands when needed in the last 7 days | T3: Total | U3: Number of household members who did not have sufficient water to wash hands when needed in the last 7 days | X3: Percent distribution by main reason for not having sufficient soap to wash hands when needed in the last 7 days | AB3: Total | AC3: Number of household members who did not have sufficient soap to wash hands when needed in the last 7 days
C4: Fixed facility (sink / tap) | D4: Mobile object (bucket / jug / kettlet) | N4: Water supply no longer available | O4: Water supply reduced | P4: Unable to access water sources | Q4: Unable to afford water | R4: Other | S4: DK / Missing | X4: Soap not available at the market | Y4: Unable to afford soap | Z4: Other | AA4: DK / Missing
B5: hh.sav mutate(hhmemwt = hhweightA*HLnum) filter(HH17 %in% c(0,1)) weight by hhmemwt | C5: WS18 %in% c(1,2) | D5: WS18 == 3 | E5: WS18 == 4 | F5: WS18 == 6 | G5: WS18 == 9 | H5: 100 | I5: WS19 == 2 | J5: WS21 == 2 | K5: total == 1 | L5: totalHL == 1 | N5: filter(WS19 == 1) - - - WS20 == 1 | O5: WS20 == 2 | P5: WS20 == 3 | Q5: WS20 == 4 | R5: WS20 == 6 | S5: WS20 >= 8 | T5: 100 | U5: total1 == 1 | V5: totalHL1 == 1 | X5: filter(WS21 == 1) - - - WS22 == 1 | Y5: WS22 == 2 | Z5: WS22 == 6 | AA5: WS22 >= 8 | AB5: 100 | AC5: total2 == 1 | AD5: totalHL2 == 1
A7: Total | B7: total == 1 | C7: p | H7: 100 | I7: p | K7: n | L7: n_unw | N7: p | T7: 100 | U7: n | V7: n_unw | X7: p | AB7: 100 | AC7: n | AD7: n_unw
A9: Area
A10: Urban | B10: area == 1 | H10: 100 | T10: 100 | AB10: 100
A11: Rural | B11: area == 2 | H11: 100 | T11: 100 | AB11: 100
A12: Education of household head
A13: Pre-primary or none | B13: headed == 0 | H13: 100 | T13: 100 | AB13: 100
A14: Primary | B14: headed == 1 | H14: 100 | T14: 100 | AB14: 100
