Workbook
Name _Toc450375517: 'JW2.9.1'!$A$2
Name _Toc450375517: 'JW2.9.3'!$A$2
Name _Toc450375517: 'JW2.9.6'!$A$2
Name _Toc450456886: 'JW2.9.4'!$A$2
Name _Toc450456886: 'JW2.9.5'!$A$2

Sheet IDX
B2: Jamaica
B3: MICS Plus
B4: 2023-24
B5: Wave 2
B7: ContentA
B9: Survey and sample characteristics | D9: COVID-19
B10: ='JW2.1.1'!A1 -> Table JW2.1.1: Response rates | D10: ='JW2.7.2'!A1 -> Table JW2.7.2: COVID-19 vaccination status
B11: ='JW2.1.2'!A1 -> Table JW2.1.2: Average number of call attempts (unweighted) | D11: ='JW2.7.2a'!A1 -> Table JW2.7.2a: Side effects of vaccine against COVID-19
B12: ='JW2.1.3'!A1 -> Table JW2.1.3: Number of call attempts (unweighted) | D12: ='JW2.7.2b'!A1 -> Table JW2.7.2b: Partially vaccinated against COVID-19
B13: ='JW2.1.4'!A1 -> Table JW2.1.4: Duration of interviews (unweighted) | D13: ='JW2.7.2c'!A1 -> Table JW2.7.2c: Hesitancy for vaccine against COVID-19 (at least one vaccine received)
B14: ='JW2.2.1'!A1 -> Table JW2.2.1: Housing characteristics | D14: ='JW2.7.3'!A1 -> Table JW2.7.3: Hesitancy - likelihood of receiving vaccine against COVID-19 (no vaccine received)
B15: ='JW2.2.1b'!A1 -> Table JW2.2.1b: Household and personal assets | D15: ='JW2.7.3a'!A1 -> Table JW2.7.3a: Hesitancy for vaccine against COVID-19 (no vaccine received)
B16: ='JW2.2.1c'!A1 -> Table JW2.2.1c: Wealth quintiles | D16: ='JW2.7.4'!A1 -> Table JW2.7.4: Attitude towards childhood vaccination
B17: ='JW2.2.2'!A1 -> Table JW2.2.2: Household composition | D17: ='JW2.7.5'!A1 -> Table JW2.7.5: Access to services based on COVID-19 vaccination status
B18: ='JW2.2.2a'!A1 -> Table JW2.2.2a: Background characteristics of household members age 1-17 years | D18: ='JW2.7.6'!A1 -> Table JW2.7.6: COVID-19 vaccination status - children age 12-17 years
B19: ='JW2.2.3'!A1 -> Table JW2.2.3: Age distribution of household population by sex (5-year age groups) | D19: ='JW2.7.6a'!A1 -> Table JW2.7.6a: Hesitancy for vaccine against COVID-19 (for children age 12-17 years)
B20: ='JW2.2.4'!A1 -> Table JW2.2.4: Birth date reporting | D20: ='JW2.7.7'!A1 -> Table JW2.7.7: COVID-19 related worries
B21: ='JW2.3.1'!A1 -> Table JW2.3.1: Highest education of household population age 3 years or above | D21: ='JW2.7.8'!A1 -> Table JW2.7.8: Coronavirus infection
B22: ='JW2.3.1a'!A1 -> Table JW2.3.1a: Education of household members age 3-24 years | D22: ='JW2.7.8a'!A1 -> Table JW2.7.8a: Healthcare for COVID-19
B24: Nutrition
B25: ='JW2.4.1'!A1 -> Table JW2.4.1: Food Insecurity Experience Scale (FIES) | D25: Water and Sanitation
B26: ='JW2.4.2'!A1 -> Table JW2.4.2: Dietary intake (children age 1-2 years) | D26: ='JW2.9.1'!A1 -> Table JW2.9.1: Use of improved and unimproved water sources
B27: ='JW2.4.3'!A1 -> Table JW2.4.3: Dietary intake (children age 3-17 years) | D27: ='JW2.9.2'!A1 -> Table JW2.9.2: Use of basic and limited drinking water services
D28: ='JW2.9.3'!A1 -> Table JW2.9.3: Availability of sufficient drinking water when needed
B29: Attitudes toward people with disability | D29: ='JW2.9.4'!A1 -> Table JW2.9.4: Use of improved and unimproved sanitation facilities
B30: ='JW2.5.1'!A1 -> Table JW2.5.1 Attitudes toward people with disabilities - Common beliefs | D30: ='JW2.9.5'!A1 -> Table JW2.9.5: Use of basic and limited sanitation services
B31: ='JW2.5.2'!A1 -> Table JW2.5.1 Attitudes toward people with disabilities - Attitudes about personal lives | D31: ='JW2.9.6'!A1 -> Table JW2.9.6: Handwashing facility and availability of water and soap to wash hands when needed
B32: ='JW2.5.3'!A1 -> Table JW2.5.3 Attitudes toward people with disabilities - Behaviours toward people with disability
B33: ='JW2.5.4'!A1 -> Table JW2.5.4 Attitudes toward people with disabilities - Inclusion of people with disability
B35: Attitudes toward people with mental illness
B36: ='JW2.6.1'!A1 -> Table JW2.6.1: Attitudes toward people with mental health problems - Mean score
B37: ='JW2.6.1a'!A1 -> Table JW2.6.1a: Attitudes toward people with mental health problems - Mean score components
B38: ='JW2.6.2'!A1 -> Table JW2.6.2: Attitudes toward people with mental health problems - tolerance and support
B39: ='JW2.6.2a'!A1 -> Table JW2.6.2a Attitudes toward people with mental health problems - prejudice and exclusion
B40: ='JW2.6.3'!A1 -> Table JW2.6.3: Use of mental health services
B41: ='JW2.6.4'!A1 -> Table JW2.6.4: Knowledge of available mental health services
B43: A The variable, 'Degree of urbanisation', has been added to tables where relevant. The degree of urbanisation is a classification system developed by the European Commission to categorise areas based on population density and settlement patterns. It divides areas into three categories: cities (densely populated areas), where at least 50% of the population resides in high-density clusters; towns and semi-dense areas (intermediate density areas), with less than 50% of the population in high-density clusters and less than 50% in rural grid cells; and rural areas (thinly populated areas), where more than 50% of the population lives in rural grid cells. This classification is based on a combination of geographical contiguity and population density, measured by minimum population thresholds applied to 1 km² population grid cells. Read more about the methodology at https://ec.europa.eu/eurostat/statistics-explained/index.php?title=Applying_the_degree_of_urbanisation_manual. For Jamaica MICS Plus, the degree of urbanisation for each MICS sampled household was calculated using MICS cluster boundaries (GIS data from Jamaica MICS 2022), the GHS Population Grid (2020) at 100-meter resolution, and the GHS Settlement Model Grid (2020) at 1-kilometer resolution, both sourced from the Global Human Settlement Layer (GHSL). The calculations were conducted using GHSL tools integrated into ArcGIS Pro, intersecting the geometry of the MICS clusters with the population grid and settlement classification grid.

Sheet Preparation File
A1: # Preparation contract: micsPlusTableR supplies hh_path and hl_path, makes its # declared imports available, and collects hh, hl, and extra-table objects. # Do not source external package or function bootstrap scripts from this file. hh <- haven::read_sav(hh_path) hl <- haven::read_sav(hl_path) # Add HHIDs hl <- hl |> mutate(HHID = HH0*1000000+HH1*1000+HH2*10+HH0A) hh <- hh |> mutate(HHID = HH0*1000000+HH1*1000+HH2*10+HH0A) |> mutate(respage_gr = case_when( respage %in% c(18:34) ~ "18-34", respage %in% c(35:64) ~ "35-64", respage %in% c(65:84) ~ "65-84", respage >= 85 ~ "85+", TRUE ~ NA_character_ )) # Add total variables hh <- hh |> mutate(total = 1) hl <- hl |> mutate(total = 1) # from hh to hl ------------------------------------------------- hh_add <- hh |> select(HHID, HLnum, ch117num, headed, stratum, FI1, FI2, FI3, FI4, FI5, FI6, FI7, FI8, headsex, headage) # hlweight and HHID ---------- hl <- hl |> left_join(hh_add, by = c("HHID")) |> mutate(hlweight = hhweight / HLnum) |> mutate(headage_gr = case_when( headage %in% c(98) ~ NA, between(headage, 0, 17) ~ "0-17", between(headage, 18, 34) ~ "18-34", between(headage, 35, 64) ~ "35-64", between(headage, 65, 84) ~ "65-84", headage >= 85 ~ "85+" )) |> group_by(HH1, HH2) |> mutate(HLnum15more = sum(if_else(HH17 %in% c(1,0) & HL7 %in% c(1, NA) & HL6 >= 15 & HL6 != 98, 1, 0))) |> ungroup() # -------------------------------------------------------- # from hl to hh ------------------------------------------ hl_add <- hl |> select(HHID, HLnum15more, hlweight) |> distinct() hh <- hh |> left_join(hl_add, by = c("HHID")) # -------------------------------------------------------- # Tables that are not producible with the common logic in the system, are produced with further code and included within the system. tables_extra <- c("JW2.4.1", "JW2.6.1", "JW2.6.1a") # Dictionary for extra tables and their corresponding outputs extra_tables_dict <- list( "JW2.4.1" = "tb_41", "JW2.6.1" = "tb_61", "JW2.6.1a" = "tb_61a" ) # Table 6.1 #library(labelled) #hh <- haven::read_sav(here::here("mics-files/JAM_W2_hh.sav")) df <- hh |> filter(HH17 %in% c(0,1)) |> select(hhweight, MHP1A, MHP1B, MHP1C, MHP1D, MHP1E, MHP1F, MHP1G, MHP1H, MHP1I, MHP1J, MHP1K, MHP1L, area, degubra, respsex, respage_gr, resped, windex5) |> mutate(hhweight = ifelse(is.na(hhweight), 0, hhweight)) # ---- shared labels ---- item_labels <- c( "Strongly agree" = 1, "Agree" = 2, "Neither agree nor disagree" = 3, "Disagree" = 4, "Strongly disagree" = 5, "DK/Missing" = 9 ) # ---- spec: item -> newvar + variable label + direction ---- spec <- list( MHP1A = list(new = "lackslfdsc", dir = "pos", lab = "One of the main causes of mental health problems is a lack of self-discipline and willpower"), MHP1B = list(new = "different", dir = "pos", lab = "There is something about people living with mental health problems that makes it easy to tell them apart from people without mental health problems"), MHP1C = list(new = "devtolatt", dir = "rev", lab = "We need to adopt a far more tolerant attitude toward people living with mehtal health problems in our society"), MHP1D = list(new = "dntdessymp", dir = "pos", lab = "People living with mental health problems don't deserve our sympathy"), MHP1E = list(new = "nextdoor", dir = "pos", lab = "I would not want to live next door to someone who has mental health problems"), MHP1F = list(new = "resneighb", dir = "pos", lab = "It is frightening to think of people with mental health problems living in residential neigbourhoods"), MHP1G = list(new = "anyothhp", dir = "rev", lab = "Mental health problems are like any other health problems"), MHP1H = list(new = "anyone", dir = "rev", lab = "Virtually anyone can have mental health problems"), MHP1I = list(new = "community", dir = "rev", lab = "The best therapy for many peiple with mental health problems is to be part of a community"), MHP1J = list(new = "lessdang", dir = "rev", lab = "People with mental health problems are far less of a danger than most people suppose"), MHP1K = list(new = "responsib", dir = "pos", lab = "People with mental health problems should not be given any responsibility"), MHP1L = list(new = "babysit", dir = "rev", lab = "Most women who were once patients in a hospital for mental health problems can be trusted as babysitters") ) # ---- apply: recode items + create scored vars + attach labels ---- for (v in names(spec)) { s <- spec[[v]] newv <- s$new # 1) recode DK/Missing on the original item: 8..9 -> 9, else copy df[[newv]] <- dplyr::if_else(df[[v]] %in% 8:9, 9, df[[v]]) # 3) variable labels #labelled::var_label(df[[v]]) <- s$lab labelled::var_label(df[[newv]]) <- s$lab # 4) value labels labelled::val_labels(df[[newv]]) <- item_labels } # build a lookup table from your spec (new variable name + direction + label) spec_lut <- tibble( variable = map_chr(spec, ~ .x$new), dir = map_chr(spec, ~ .x$dir), item_lab = map_chr(spec, ~ .x$lab) ) df_long <- df |> select( hhweight, area, degubra, respsex, respage_gr, resped, windex5, anyone, devtolatt, community, anyothhp, lessdang, babysit, dntdessymp, nextdoor, resneighb, responsib, lackslfdsc, different ) |> pivot_longer( cols = -c(hhweight, area, degubra, respsex, respage_gr, resped, windex5), names_to = "variable", values_to = "label" ) |> left_join(spec_lut, by = "variable") |> mutate( score = case_when( label == 1 ~ if_else(dir == "pos", 0, 100), label == 2 ~ if_else(dir == "pos", 25, 75), label == 3 ~ 50, label == 4 ~ if_else(dir == "pos", 75, 25), label == 5 ~ if_else(dir == "pos", 100, 0), TRUE ~ NA_real_ # includes 9 (DK/Missing) and NA ) ) # ------------------------- # Table prep # ------------------------- # Local tabulation helpers for the JAM W2 extra tables. Labelled categories # retain their survey-code order; # unlabelled categories retain their first-observed order. prep_factor <- function(x) { labels <- attr(x, "labels", exact = TRUE) if (!is.null(labels)) { ordered_labels <- trimws( names(labels)[order(as.numeric(unname(labels)), na.last = TRUE)] ) labelled_values <- haven::as_factor(x, levels = "labels") return(factor( trimws(as.character(labelled_values)), levels = ordered_labels )) } if (is.factor(x)) return(x) factor(x, levels = unique(x[!is.na(x)])) } weighted_mean <- function(x, weight) { keep <- !is.na(x) & !is.na(weight) if (!any(keep)) return(NA_real_) denominator <- sum(weight[keep]) if (!is.finite(denominator) || denominator == 0) return(NA_real_) sum(x[keep] * weight[keep]) / denominator } count_by_stub <- function(design, group_vars) { count_data <- design$variables count_weight <- as.numeric(stats::weights(design)) grouped_counts <- lapply(group_vars, function(group_var) { stub_values <- prep_factor(count_data[[group_var]]) stub_levels <- levels(stub_values) tibble::tibble( group_cat = stub_levels, count_unw = unname(vapply(stub_levels, function(stub) { as.numeric(sum(!is.na(stub_values) & stub_values == stub)) }, numeric(1))), count_w = unname(vapply(stub_levels, function(stub) { sum(count_weight[!is.na(stub_values) & stub_values == stub]) }, numeric(1))) ) }) dplyr::bind_rows( tibble::tibble( group_cat = "Total", count_unw = as.numeric(nrow(count_data)), count_w = sum(count_weight) ), grouped_counts ) } df2 <- survey::svydesign(ids = ~1, weights = ~hhweight, data = df_long) tb_perc <- local({ table_data <- df2$variables table_weight <- as.numeric(stats::weights(df2)) group_values <- prep_factor(table_data$variable) category_values <- prep_factor(table_data$label) group_levels <- levels(group_values) category_levels <- levels(category_values) percentages <- tidyr::expand_grid( group_cat = group_levels, category = category_levels ) percentages$value <- vapply(seq_len(nrow(percentages)), function(i) { in_group <- !is.na(group_values) & group_values == percentages$group_cat[[i]] & !is.na(category_values) denominator <- sum(table_weight[in_group]) in_category <- in_group & category_values == percentages$category[[i]] 100 * sum(table_weight[in_category]) / denominator }, numeric(1)) dplyr::bind_rows( percentages, tibble::tibble( group_cat = group_levels, category = "Total", value = 100 ) ) |> tidyr::pivot_wider(names_from = category, values_from = value) }) tb_score <- local({ table_data <- df2$variables table_weight <- as.numeric(stats::weights(df2)) group_values <- prep_factor(table_data$variable) group_levels <- sort(levels(group_values)) tibble::tibble( group_cat = group_levels, score = unname(vapply(group_levels, function(group) { in_group <- !is.na(group_values) & group_values == group weighted_mean(table_data$score[in_group], table_weight[in_group]) }, numeric(1))) ) }) tb_61 <- tb_perc |> left_join(tb_score, by = c("group_cat")) assign("tb_61", tb_61, envir = .GlobalEnv) # ---------------------------------------------------------- # Table 6.1a ---- # ---------------------------------------------------------- df_long2 <- df_long |> mutate(variable2 = case_when( variable %in% c("anyone", "devtolatt", "community", "anyothhp", "lessdang", "babysit") ~ "tolerance", variable %in% c("dntdessymp", "nextdoor", "resneighb", "responsib", "lackslfdsc", "different") ~ "prejudice", TRUE ~ variable )) df3 <- survey::svydesign(ids = ~1, weights = ~hhweight, data = df_long2) score_group_vars <- c( "area", "degubra", "respsex", "respage_gr", "resped", "windex5" ) tb_score2 <- local({ table_data <- df3$variables table_weight <- as.numeric(stats::weights(df3)) score_group <- prep_factor(table_data$variable2) score_group_levels <- sort(levels(score_group)) make_score_row <- function(category, in_category) { scores <- c( Total = weighted_mean( table_data$score[in_category], table_weight[in_category] ), stats::setNames(vapply(score_group_levels, function(group) { selected <- in_category & !is.na(score_group) & score_group == group weighted_mean(table_data$score[selected], table_weight[selected]) }, numeric(1)), score_group_levels) ) tibble::as_tibble_row(c(list(category = category), as.list(scores))) } category_rows <- lapply(score_group_vars, function(group_var) { category_values <- prep_factor(table_data[[group_var]]) lapply(levels(category_values), function(category) { make_score_row( category, !is.na(category_values) & category_values == category ) }) }) dplyr::bind_rows( make_score_row("Total", rep(TRUE, nrow(table_data))), unlist(category_rows, recursive = FALSE) ) }) df4 <- survey::svydesign(ids = ~1, weights = ~hhweight, data = df) tb_n <- count_by_stub(df4, score_group_vars) |> dplyr::relocate(count_unw, .after = count_w) tb_61a <- tb_score2 |> left_join(tb_n, by = c("category" = "group_cat")) assign("tb_61a", tb_61a, envir = .GlobalEnv) # Table 4.1 # The code creates an object named hh that corresponds to out use, so the hh used in our data is saved in name hhx, and after table 4.1 it is recalled from here. Save hh in the project to hhx hhx <- hh group_vars <- c("area", "degubra", "headsex", "headage_gr", "headed", "windex5" ) # path_fies and path_fies_output are supplied by micsPlusTableR from the # selected preparation folder and configured main output folder. stopifnot(dir.exists(path_fies), dir.exists(path_fies_output)) assign("hh_path", hh_path, envir = .GlobalEnv) assign("hl_path", hl_path, envir = .GlobalEnv) # Run the script for FIES computations source(paste0(path_fies, "/JAM MICSPlus Wave2 - Table 4.1_Script.R")) res.df[[1]] |> dplyr::select(Disaggregation, P_mod, P_sev) c1 <- res.df$PrevalenceRates |> dplyr::select(Disaggregation, P_sev, P_mod, N) |> mutate(P_sev = as.numeric(P_sev) * 100, P_mod = as.numeric(P_mod) * 100, `Moderate food insecurity` = P_mod - P_sev) |> relocate(`Moderate food insecurity`, .after = 1) |> mutate(N = as.numeric(N)) |> mutate(across(where(is.numeric), ~ replace_na(.x, 0))) |> dplyr::rename(stub = Disaggregation) |> filter(!stub %in% c("area", "degubra", "headsex", "headage", "headed", "windex5")) # HL hlx <- hl |> dplyr::filter(HL7 %in% c(1,NA)) hlx_des <- hlx |> # Population level as_survey_design( weights = hhweight ) dfx <- hlx_des |> dplyr::select(FI1:FI8, hhweight, dplyr::all_of(group_vars)) |> mutate(across(FI1:FI8, ~ case_when( . %in% c("YES", 1) ~ 1, . %in% c("NO", 2) ~ 2, . %in% c("DK", 9) ~ NA_real_, TRUE ~ NA_real_ ))) |> # Drop rows where any column from FI1 to FI8 is NA drop_na(FI1:FI8) c2 <- count_by_stub(dfx, group_vars) |> dplyr::rename(stub = group_cat) tb_41 <- c1 |> left_join(c2, by = c("stub")) |> select(-c(N)) |> relocate(count_unw, .after = count_w) assign("tb_41", tb_41, envir = .GlobalEnv) hh <- hhx # FIES scripts create the output folder and write reports directly to path_fies_output.

Sheet JW2.1.1
A1: Table JW2.1.1: Response rates | K1: IDX
A2: Number of households by interview results, by area of residence, Jamaica MICS Plus 2023-2024, Wave 2
C3: Total | D3: Area | G3: Degree of urbanisation
D4: Urban | E4: Rural | G4: City | H4: Town & Semi-dense area | I4: Rural area
B5: hh.sav filter(total == 1) | C5: total == 1 | D5: area == 1 | E5: area == 2 | G5: degubra == 1 | H5: degubra == 2 | I5: degubra == 3
A7: Households sampled | B7: total == 1 | C7: n_unw
A9: Interviewed | B9: HH17 %in% c(0,1)
A10: No consent for next wave | B10: HH17 == 0
A11: With consent for next wave | B11: HH17 == 1
A12: Refused | B12: HH17 %in% c(2,3)
A13: No consent for next wave | B13: HH17 == 2
A14: With consent for next wave | B14: HH17 == 3
A15: No eligible respondent | B15: HH17 == 4
A16: Phone number(s) does not belong to sampled household | B16: HH17 == 5
A17: Phone number(s) inactive | B17: HH17 == 6
A18: Respondent busy / postponed | B18: HH17 == 7
A19: No response after repeated call attempts or phone(s) turned off | B19: HH17 == 8
A20: Other | B20: HH17 == 96
A21: Not called in current waveA | B21: HH17 == 97
A23: Response rate | B23: HH17 %in% c(0,1) | C23: mean_unw
A24: A The following households are not called in the current wave: - Households that were interviewed in the previous wave but did not provide consent for the current wave

Sheet JW2.1.2
A1: Table JW2.1.2: Average number of call attempts (unweighted) | K1: IDX
A2: Average number of call attempts by interview resultsA, by area of residence, Jamaica MICS Plus 2023-2024, Wave 2
C3: Total | D3: Area | G3: Degree of urbanisation
D4: Urban | E4: Rural | G4: City | H4: Town & Semi-dense area | I4: Rural area
B5: hh.sav filter(HH17 != 97) | C5: total == 1 | D5: area == 1 | E5: area == 2 | G5: degubra == 1 | H5: degubra == 2 | I5: degubra == 3
A7: Total | B7: total == 1 | C7: mean_unw(CAnum)
A9: Interviewed | B9: HH17 %in% c(0,1)
A10: No consent for next wave | B10: HH17 == 0
A11: With consent for next wave | B11: HH17 == 1
A12: Refused | B12: HH17 %in% c(2,3)
A13: No consent for next wave | B13: HH17 == 2
A14: With consent for next wave | B14: HH17 == 3
A15: No eligible respondent | B15: HH17 == 4
A16: Phone number(s) does not belong to sampled household | B16: HH17 == 5
A17: Phone number(s) inactive | B17: HH17 == 6
A18: Respondent busy/postponed | B18: HH17 == 7
A19: No response after repeated call attempts or phone number(s) turned off | B19: HH17 == 8
A20: A It does not include households with the response code 'Not called in current wave'

Sheet JW2.1.3
A1: Table JW2.1.3: Number of call attempts (unweighted) | I1: IDX
A2: Percent and frequency of households by number of call attempts and completion status of interview, Jamaica MICS Plus 2023-2024, Wave 2
C3: Completed interviews | F3: Incomplete interviewsA
C4: Number | D4: Percent | F4: Number | G4: Percent
B5: hh.sav filter(HH17 != 97) | C5: HH17 %in% c(0,1) | D5: HH17 %in% c(0,1) | F5: !(HH17 %in% c(0,1)) | G5: !(HH17 %in% c(0,1))
A7: Total | B7: total == 1 | C7: n_unw | D7: p_unw | F7: n_unw | G7: p_unw
A9: 1 | B9: CAnum == 1
A10: 2 | B10: CAnum == 2
A11: 3 | B11: CAnum == 3
A12: 4 | B12: CAnum == 4
A13: 5 | B13: CAnum == 5
A14: 6 | B14: CAnum == 6
A15: 7 | B15: CAnum == 7
A16: 8 | B16: CAnum == 8
A17: 9 | B17: CAnum == 9
A18: 10+ | B18: CAnum >= 10
A19: A It does not include households with the response code 'Not called in current wave'

Sheet JW2.1.4
A1: Table JW2.1.4: Duration of interviews (unweighted) | G1: IDX
A2: Mean and median duration of interviews in minutes, Jamaica MICS Plus 2023-2024, Wave 2
C3: Duration of interviews (minutes) | E3: Number of householdsA
C4: Mean | D4: Median
B5: hh.sav filter(HH17 %in% c(0,1) & intduration != 97) | C5: total == 1 | D5: total == 1 | E5: total == 1
A7: Total | B7: total == 1 | C7: mean_unw(intduration) | D7: median_unw(intduration) | E7: n_unw
A9: Area
A10: Urban | B10: area == 1
A11: Rural | B11: area == 2
A12: Degree of urbanization
A13: City | B13: degubra == 1
A14: Town & Semi-dense area | B14: degubra == 2
A15: Rural area | B15: degubra == 3
A16: Sex of respondent
A17: Male | B17: respsex == 1
A18: Female | B18: respsex == 2
A19: Age of respondent
A20: 18-34 | B20: between(respage,18,34)
A21: 35-64 | B21: between(respage,35,64)
A22: 65-84 | B22: between(respage,65,84)
A23: 85+ | B23: between(respage,85,95)
A24: Education of respondent
A25: Primary or less | B25: resped == 1
A26: Lower secondary | B26: resped == 2
A27: Upper secondary | B27: resped == 3
A28: Post secondary + | B28: resped == 4
A29: Special education | B29: resped == 5
A30: Inconsistent / DK / Missing | B30: resped == 8
A31: Number of household members
A32: 1-2 | B32: between(HLnum,1,2)
A33: 3-4 | B33: between(HLnum,3,4)
A34: 5-6 | B34: between(HLnum,5,6)
A35: 7+ | B35: HLnum >= 7
A36: A 148 households are excluded from the calculation of mean and median durations of interview, due to interrupted calls and inconsistent information

Sheet JW2.2.1
A1: Table JW2.2.1: Housing characteristics | K1: IDX
A2: Percent distribution of households by selected housing characteristics, by area of residence, Jamaica MICS Plus 2023-2024, Wave 2
C3: Total | D3: Area | G3: Degree of urbanisation
D4: Urban | E4: Rural | G4: City | H4: Town & Semi-dense area | I4: Rural area
B5: hh.sav filter(HH17 %in% c(0,1)) weight by hhweight | C5: total == 1 | D5: area == 1 | E5: area == 2 | G5: degubra == 1 | H5: degubra == 2 | I5: degubra == 3
A7: Total | B7: total == 1 | C7: p
A9: Internet access at home
A10: Yes | B10: CH12 == 1
A11: No | B11: CH12 == 2
A12: Missing | B12: CH12 == 9
A13: Electricity
A14: Yes, interconnected grid | B14: CH9 == 1
A15: Yes, off-grid (generator/ isolated system) | B15: CH9 == 2
A16: No | B16: CH9 == 3
A17: Missing | B17: CH9 == 9
A18: Number of rooms used for sleeping
A19: 1 | B19: CH7 == 1
A20: 2 | B20: CH7 == 2
A21: 3+ | B21: between(CH7,3,96)
A22: Inconsistent | B22: CH7 == 97
A23: Mean number of persons per room used for sleeping | B23: mutate(perssleeproom = HLnum / CH7) !(between(CH7,97,99)) | C23: mean(perssleeproom)
A25: Number of households | B25: total == 1 | C25: n

Sheet JW2.2.1b
A1: Table JW2.2.1b: Household and personal assets | K1: IDX
A2: Percentage of households by ownership of selected household and personal assets, by area of residence, Jamaica MICS Plus 2023-2024, Wave 2
C3: Total | D3: Area | G3: Degree of urbanisation
D4: Urban | E4: Rural | G4: City | H4: Town & Semi-dense area | I4: Rural area
B5: hh.sav filter(HH17 %in% c(0,1)) weight by hhweight | C5: total == 1 | D5: area == 1 | E5: area == 2 | G5: degubra == 1 | H5: degubra == 2 | I5: degubra == 3
A7: Percentage that own a
A8: Fixed telephone line | B8: CH8A == 1 | C8: p
A9: Chair | B9: CH8B == 1
A10: Table | B10: CH8C == 1
A11: Sofa | B11: CH8D == 1
A12: Kitchen cupboard/cabinet | B12: CH8E == 1
A13: Water storage tank | B13: CH8F == 1
A14: Clothes closet/wardrobe | B14: CH8G == 1
A15: Television | B15: CH10A == 1
A16: Refrigerator | B16: CH10B == 1
A17: Gas or electric stove | B17: CH10C == 1
A18: Microwave oven | B18: CH10D == 1
A19: Air conditioner | B19: CH10E == 1
A20: Fan | B20: CH10F == 1
... A23: Computer or tablet | B23: CH10I == 1
A24: Percentage where at least one member owns or has a
A25: Wristwatch | B25: CH11A == 1
A26: Car, truck, or van | B26: CH11B == 1
A27: Bank account | B27: CH13 == 1
A29: Number of households | B29: total == 1 | C29: n

Sheet JW2.2.1c
A1: Table JW2.2.1c: Wealth quintiles | K1: IDX
A2: Percent distribution of household population, by wealth index quintile, Jamaica MICS Plus 2023-2024, Wave 2
C3: Percent distribution by wealth index quintiles | H3: Total | I3: Number of household members
C4: Poorest | D4: Second | E4: Middle | F4: Fourth | G4: Richest
B5: hl.sav filter(HL7 %in% c(1,NA)) weight by hhweight | C5: windex5 == 1 | D5: windex5 == 2 | E5: windex5 == 3 | F5: windex5 == 4 | G5: windex5 == 5 | H5: 100 | I5: total == 1 | J5: total == 1
A7: Total | B7: total == 1 | C7: p | H7: 100 | I7: n | J7: n_unw
A9: Area
A10: Urban | B10: area == 1 | H10: 100
A11: Rural | B11: area == 2 | H11: 100
A12: Degree of urbanization
A13: City | B13: degubra == 1 | H13: 100
A14: Town & Semi-dense area | B14: degubra == 2 | H14: 100
A15: Rural area | B15: degubra == 3 | H15: 100

Sheet JW2.2.2
A1: Table JW2.2.2: Household composition | G1: IDX
A2: Percent and frequency distribution of households, Jamaica MICS Plus 2023-2024, Wave 2
C3: Weighted percent | D3: Number of households
D4: Weighted | E4: Unweighted
B5: hh.sav filter(HH17 %in% c(0,1)) weight by hhweight | C5: total == 1 | D5: total == 1 | E5: total == 1
A7: Total | B7: total == 1 | C7: p(100) | D7: n | E7: n_unw
A9: Area
A10: Urban | B10: area == 1
A11: Rural | B11: area == 2
A12: Degree of urbanization
A13: City | B13: degubra == 1
A14: Town & Semi-dense area | B14: degubra == 2
A15: Rural area | B15: degubra == 3
A16: Sex of household head
A17: Male | B17: headsex == 1
A18: Female | B18: headsex == 2
A19: Age of household head
A20: 18-34 | B20: between(headage,18,34)
A21: 35-64 | B21: between(headage,35,64)
A22: 65-84 | B22: between(headage,65,84)
A23: 85+ | B23: between(headage,85,95)
A24: Education of household head
A25: Primary or less | B25: headed == 1
A26: Lower secondary | B26: headed == 2
A27: Upper secondary | B27: headed == 3
A28: Post secondary+ | B28: headed == 4
A29: Special education | B29: headed == 5
A30: Inconsistent / DK / Missing | B30: headed == 8
A31: Number of household members
A32: 1-2 | B32: between(HLnum,1,2)
A33: 3-4 | B33: between(HLnum,3,4)
A34: 5-6 | B34: between(HLnum,5,6)
A35: 7+ | B35: HLnum >= 7
A36: Wealth index quintile
A37: Poorest | B37: windex5 == 1
A38: Second | B38: windex5 == 2
A39: Middle | B39: windex5 == 3
A40: Fourth | B40: windex5 == 4
A41: Richest | B41: windex5 == 5
A43: Mean household size | B43: total == 1 | C43: mean(HLnum) | D43: n1 | E43: n_unw1

Sheet JW2.2.2a
A1: Table JW2.2.2a: Background characteristics of household members age 1-17 years | G1: IDX
A2: Percent and frequency distribution of household members age 1-17 yearsA, Jamaica MICS Plus 2023-2024, Wave 2
C3: Weighted percent | D3: Number of household members age 1-17 years
D4: Weighted | E4: Unweighted
B5: hl.sav filter(HL7 %in% c(1,NA) & between(HL6,1,17)) weight by hhweight | C5: total == 1 | D5: total == 1 | E5: total == 1
A7: Total | B7: total == 1 | C7: p(100) | D7: n | E7: n_unw
A9: Area
A10: Urban | B10: area == 1
A11: Rural | B11: area == 2
A12: Degree of urbanization
A13: City | B13: degubra == 1
A14: Town & Semi-dense area | B14: degubra == 2
A15: Rural area | B15: degubra == 3
A16: Sex
A17: Male | B17: HL4 == 1
A18: Female | B18: HL4 == 2
A19: Age
A20: 1-4 | B20: between(HL6,1,4)
A21: 1-2 | B21: between(HL6,1,2)
A22: 3-4 | B22: between(HL6,3,4)
A23: 5-9 | B23: between(HL6,5,9)
A24: 10-14 | B24: between(HL6,10,14)
A25: 10-11 | B25: between(HL6,10,11)
A26: 12-14 | B26: between(HL6,12,14)
A27: 15-17 | B27: between(HL6,15,17)
A28: Education of household head
A29: Primary or less | B29: headed == 1
A30: Lower secondary | B30: headed == 2
A31: Upper secondary | B31: headed == 3
A32: Post secondary+ | B32: headed == 4
A33: Special education | B33: headed == 5
A34: Inconsistent / DK / Missing | B34: headed == 8
A35: Wealth index quintile
A36: Poorest | B36: windex5 == 1
A37: Second | B37: windex5 == 2
A38: Middle | B38: windex5 == 3
A39: Fourth | B39: windex5 == 4
A40: Richest | B40: windex5 == 5
A41: A In households with more than one member age 1-17 years, one of the members is randomly selected. The sample weight for the selected member is obtained as the multiplication of the household weight with the total number of members age 1-17 years in the household. This table is based on all members age 1-17 years listed in households where interviews were completed. The age and sex distribution of members age 1-17 years in this table is not identical to those found in the rest of the tables for this age group as the findings are based on data collected on one randomly selected member, the age and sex distribution of whom could be slightly different due to random selection.

Sheet JW2.2.3
A1: Table JW2.2.3: Age distribution of household population by sex (5-year age groups) | L1: IDX
A2: Percent and frequency distribution of household population, by 5-year age groups and sex, Jamaica MICS Plus 2023-2024, Wave 2
C3: Males | F3: Females | I3: Total
C4: Number | D4: Percent | F4: Number | G4: Percent | I4: Number | J4: Percent
B5: hl.sav filter(HL7 %in% c(1,NA)) weight by hhweight | C5: HL4 == 1 | D5: HL4 == 1 | F5: HL4 == 2 | G5: HL4 == 2 | I5: total == 1 | J5: total == 1
A7: Total | B7: total == 1 | C7: n | D7: p(100) | F7: n | G7: p(100) | I7: n | J7: p(100)
A9: Age
A10: 0-4 | B10: between(HL6,0,4)
A11: 0 | B11: HL6 == 0
A12: 1-2 | B12: between(HL6,1,2)
A13: 3-4 | B13: between(HL6,3,4)
A14: 5-9 | B14: between(HL6,5,9)
A15: 10-14 | B15: between(HL6,10,14)
A16: 10-11 | B16: between(HL6,10,11)
A17: 12-14 | B17: between(HL6,12,14)
A18: 15-19 | B18: between(HL6,15,19)
A19: 15-17 | B19: between(HL6,15,17)
A20: 18-19 | B20: between(HL6,18,19)
A21: 20-24 | B21: between(HL6,20,24)
... A34: 85+ | B34: between(HL6,85,95)

Sheet JW2.2.4
A1: Table JW2.2.4: Birth date reporting | J1: IDX
A2: Percent distribution of household population, by completeness of reporting of date of birth and ageA, Jamaica MICS Plus 2023-2024, Wave 2
C3: Percent distribution by completeness of reporting of date of birth and age | G3: Total | H3: Number of household members
C4: Year and month of birth (calculated age) | D4: Reported age
D5: Year of birth only | E5: Month of birth only | F5: Neither year nor month of birth
B6: hl.sav filter(HL7 %in% c(1,NA)) weight by hhweight | C6: HL5M < 98 & HL5Y < 9998 | D6: HL5Y < 9998 & HL5M >= 98 | E6: HL5Y >= 9998 & HL5M < 98 | F6: HL5M >= 98 & HL5Y >= 9998 | G6: 100 | H6: total == 1 | I6: total == 1
A8: Total | B8: total == 1 | C8: p | G8: 100 | H8: n | I8: n_unw
A10: Area
A11: Urban | B11: area == 1 | G11: 100
A12: Rural | B12: area == 2 | G12: 100
A13: Degree of urbanization
A14: City | B14: degubra == 1 | G14: 100
A15: Town & Semi-dense area | B15: degubra == 2 | G15: 100
A16: Rural area | B16: degubra == 3 | G16: 100
A17: Age
A18: 0-17 | B18: between(HL6,0,17) | G18: 100
A19: 18-34 | B19: between(HL6,18,34) | G19: 100
A20: 35-64 | B20: between(HL6,35,64) | G20: 100
A21: 65-84 | B21: between(HL6,65,84) | G21: 100
A22: 85+ | B22: between(HL6,85,95) | G22: 100
A23: A In MICS Plus questionnaire, age of a household member is calculated if both year and month of birth information available and only asked if either year or month of birth information not available. Thus, for all household members, age information would be available.

Sheet JW2.3.1
A1: Table JW2.3.1: Highest education of household population age 3 years or above | L1: IDX
A2: Percent distribution of household members age 3 years or above by highest level of education attended, Jamaica MICS Plus 2023-2024, Wave 2
C3: Percent distribution by level of highest education attended | I3: Total | J3: Number of household members age 3 years or above
C4: Primary or less | D4: Lower secondary | E4: Upper secondary | F4: Post secondary+ | G4: Special education | H4: Inconsistent / DK / Missing
B5: hl.sav filter(HL7 %in% c(1,NA) & HL6 >= 3) weight by hhweight | C5: edlevel == 1 | D5: edlevel == 2 | E5: edlevel == 3 | F5: edlevel == 4 | G5: edlevel == 5 | H5: edlevel %in% c(8, NA) | I5: 100 | J5: total == 1 | K5: total == 1
A7: Total | B7: total == 1 | C7: p | I7: 100 | J7: n | K7: n_unw
A9: Area
A10: Urban | B10: area == 1 | I10: 100
A11: Rural | B11: area == 2 | I11: 100
A12: Degree of urbanization
A13: City | B13: degubra == 1 | I13: 100
A14: Town & Semi-dense area | B14: degubra == 2 | I14: 100
A15: Rural area | B15: degubra == 3 | I15: 100
A16: Sex
A17: Male | B17: HL4 == 1 | I17: 100
A18: Female | B18: HL4 == 2 | I18: 100
A19: Age
A20: 3-17 | B20: between(HL6,3,17) | I20: 100
A21: 3-5 | B21: between(HL6,3,5) | I21: 100
A22: 6-11 | B22: between(HL6,6,11) | I22: 100
A23: 12-14 | B23: between(HL6,12,14) | I23: 100
A24: 15-17 | B24: between(HL6,15,17) | I24: 100
A25: 18-34 | B25: between(HL6,18,34) | I25: 100
A26: 35-64 | B26: between(HL6,35,64) | I26: 100
A27: 65-84 | B27: between(HL6,65,84) | I27: 100
A28: 85+ | B28: between(HL6,85,95) | I28: 100
A29: Wealth index quintile
A30: Poorest | B30: windex5 == 1 | I30: 100
A31: Second | B31: windex5 == 2 | I31: 100
A32: Middle | B32: windex5 == 3 | I32: 100
A33: Fourth | B33: windex5 == 4 | I33: 100
A34: Richest | B34: windex5 == 5 | I34: 100

Sheet JW2.3.1a
A1: Table JW2.3.1a: Education of household members age 3-24 years | Q1: IDX
A2: Percentage of household members age 3-24 years who ever attended school or any early childhood education (ECE) programme and percent distribution by level of education currently attending, Jamaica MICS Plus 2023-2024, Wave 2
C3: Percentage who ever attended school or any ECE programme, in class or remotely | D3: Percentage who are currently attending school or any ECE programme, in class or remotely | E3: Number of household members age 3-24 years | G3: Percent distribution by level of education currently attending | N3: Total | O3: Number of household members age 3-24 years currently attending school or any ECE programme, in class or remotely
G4: Early childhood education | H4: Primary | I4: Lower secondary | J4: Upper secondary | K4: Post secondary+ | L4: Special education | M4: Inconsistent / DK / Missing
B5: hl.sav filter(HL7 %in% c(1,NA)) weight by hhweight | C5: filter(between(HL6,3,24)) - - - ED4 == 1 | D5: ED9 == 1 | E5: total == 1 | F5: total == 1 | G5: filter(between(HL6,3,24) & (ED9 == 1)) - - - ED10A == 0 | H5: ED10A == 1 | I5: ED10A == 2 | J5: ED10A == 3 | K5: ED10A == 4 | L5: ED10A == 5 | M5: ED10A %in% c(7,8,9) | N5: total == 1 | O5: total == 1 | P5: total == 1
A7: Total | B7: total == 1 | C7: p | E7: n | F7: n_unw | G7: p | N7: 100 | O7: n | P7: n_unw
A9: Area
A10: Urban | B10: area == 1 | N10: 100
A11: Rural | B11: area == 2 | N11: 100
A12: Degree of urbanization
A13: City | B13: degubra == 1 | N13: 100
A14: Town & Semi-dense area | B14: degubra == 2 | N14: 100
A15: Rural area | B15: degubra == 3 | N15: 100
A16: Sex
A17: Male | B17: HL4 == 1 | N17: 100
A18: Female | B18: HL4 == 2 | N18: 100
A19: Age
A20: 3-5 | B20: between(HL6,3,5) | N20: 100
A21: 6-11 | B21: between(HL6,6,11) | N21: 100
A22: 12-14 | B22: between(HL6,12,14) | N22: 100
A23: 15-17 | B23: between(HL6,15,17) | N23: 100
A24: 18-24 | B24: between(HL6,18,24) | N24: 100
A25: Education of household head
A26: Primary or less | B26: headed == 1 | N26: 100
A27: Lower secondary | B27: headed == 2 | N27: 100
A28: Upper secondary | B28: headed == 3 | N28: 100
A29: Post secondary+ | B29: headed == 4 | N29: 100
A30: Special education | B30: headed == 5 | N30: 100
A31: Inconsistent / DK / Missing | B31: headed == 8 | N31: 100
A32: Wealth index quintile
A33: Poorest | B33: windex5 == 1 | N33: 100
A34: Second | B34: windex5 == 2 | N34: 100
A35: Middle | B35: windex5 == 3 | N35: 100
A36: Fourth | B36: windex5 == 4 | N36: 100
A37: Richest | B37: windex5 == 5 | N37: 100

Sheet JW2.4.1
A1: Table JW2.4.1: Food Insecurity Experience Scale (FIES) | H1: IDX
A2: Percentage of household population experiencing moderate to severe food insecurity, based on the Food Insecurity Experience Scale, Jamaica MICS Plus, 2023-2024, Wave 2
C3: Percentage of household members experiencing food insecurity | E3: Percentage of household members experiencing moderate to severe food insecurity | F3: Number of household membersA
C4: Moderate food insecurity | D4: Severe food insecurity
B5: hh.sav mutate(hhmemwt = hhweight*HLnum) filter(HH17 %in% c(0,1)) weight by hhmemwt | C5: ph | D5: ph | E5: ph | F5: total == 1 | G5: totalHL == 1
A7: Total | B7: total == 1 | C7: mean | F7: n | G7: n_unw
A9: Area
A10: Urban | B10: area == 1
A11: Rural | B11: area == 2
A12: Degree of urbanization
A13: City | B13: degubra == 1
A14: Town & Semi-Dense area | B14: degubra == 2
A15: Rural area | B15: degubra == 3
A16: Sex of household head
A17: MALE | B17: HL4 == 1
A18: FEMALE | B18: HL4 == 2
A19: Age of household head
A20: 18-34 | B20: between(HL6,18,34)
A21: 35-64 | B21: between(HL6,35,64)
A22: 65-84 | B22: between(HL6,65,84)
A23: 85+ | B23: HL6 >= 85
A24: Education of household head
A25: Primary or less | B25: headed == 1
A26: Lower secondary | B26: headed == 2
A27: Upper secondary | B27: headed == 3
A28: Post secondary+ | B28: headed == 4
A29: Special education | B29: headed == 5
A30: DK / Missing | B30: headed == 8
A31: Wealth index quintile
A32: Poorest | B32: windex5 == 1
A33: Second | B33: windex5 == 2
A34: Middle | B34: windex5 == 3
A35: Fourth | B35: windex5 == 4
A36: Richest | B36: windex5 == 5
A37: A The FIES prevalence rates are calculated on the data from the households with no any missing info on the FIES items. Hence, it is number household members in such households.

Sheet JW2.4.2
A1: Table JW2.4.2: Dietary intake (children age 1-2 years) | AK1: IDX
A2: Percentage of children age 1-2 years according to dietary intake, Jamaica MICS Plus 2023-2024, Wave 2
C3: Percentage who: | F3: Percentage who: | I3: DK/ Missing | J3: Total | L3: Percentage who: | O3: DK/ Missing | P3: Total | R3: Percentagewho eat snacks such as pototo/ banana chips | U3: DK | V3: Total | X3: Percentage who eat fast foods such as burgers, pizza, fried chicken | AA3: DK/ Missing | AB3: Total | AD3: Percentage who: | AG3: DK | AH3: Total | AI3: Number of children age 1-2 years
C4: Have ever breastfed | D4: Are currently breastfed | F4: Don't eat fruits | G4: Eat some fruits but less than the recommended numberA of servings per day | H4: Eat at least the recommended numberA of servings of fruits per day | L4: Don't eat vegetables | M4: Eat some vegetables but less than the recommended numberB of servings per day | N4: Eat at least the recommended numberB of servings of vegetables per day | R4: Once per week or less | S4: 2-4 times per week | T4: 5 or more times per week | X4: Once per week or less | Y4: 2-4 times per week | Z4: 5 or more times per week | AD4: Don't drink soda / sugary drinks | AE4: Drink less than 2 cups of soda / sugary drinks per day | AF4: Drink 2 cups or more of soda/sugary drinks per day
B5: hh.sav filter(HH17 %in% c(0,1) & between(RS2B,1,2)) weight by ch117weight | C5: DI2 == 1 | D5: DI3 == 1 | F5: mutate(DI4 = DI4U*100+DI4N) between(DI4,0,100) | G5: DI4 == 101 | between(DI4,201,210) | between(DI4,301,310) | H5: between(DI4,102,111) | DI4 == 222 | I5: DI4 %in% c(199,299,399,998,999) | J5: 100 | L5: mutate(DI6 = DI6U*100+DI6N) between(DI6,0,100) | M5: DI6 %in% c(101,102) | between(DI6,201,210) | between(DI6,301,310) | N5: between(DI6,103,111) | DI6 %in% c(212, 1, 3) | O5: DI6 %in% c(199,299,399,998, 999) | P5: 100 | R5: mutate(DI7 = DI7U*100+DI7N) between(DI7,0,100) | DI7 == 201 | between(DI7,301,304) | S5: between(DI7,202,204) | between(DI7,305,309) | T5: between(DI7,101,110) | between(DI7,205,210) | U5: DI7 %in% c(199,299,399,998,999) | V5: 100 | X5: mutate(DI8 = DI8U*100+DI8N) between(DI8,0,100) | DI8 == 201 | between(DI8,301,304) | Y5: between(DI8,202,204) | between(DI8,305,309) | Z5: between(DI8,101,110) | between(DI8,205,210) | AA5: DI8 %in% c(199,299,399,998,999) | AB5: 100 | AD5: mutate(DI9 = DI9U*100+DI9N) between(DI9,0,100) | AE5: DI9 == 101 | between(DI9,201,210) | between(DI9,301,324) | AF5: between(DI9,102,110) | DI9 == 230 | AG5: DI9 %in% c(199,299,399,998,999) | AH5: 100 | AI5: total == 1 | AJ5: total == 1
A7: Total | B7: total == 1 | C7: mean | F7: p | J7: 100 | L7: p | P7: 100 | R7: p | V7: 100 | X7: p | AB7: 100 | AD7: p | AH7: 100 | AI7: n | AJ7: n_unw
A9: Area
A10: Urban | B10: area == 1 | J10: 100 | P10: 100 | V10: 100 | AB10: 100 | AH10: 100
A11: Rural | B11: area == 2 | J11: 100 | P11: 100 | V11: 100 | AB11: 100 | AH11: 100
A12: Degree of urbanization
A13: City | B13: degubra == 1 | J13: 100 | P13: 100 | V13: 100 | AB13: 100 | AH13: 100
A14: Town & Semi-dense area | B14: degubra == 2 | J14: 100 | P14: 100 | V14: 100 | AB14: 100 | AH14: 100
A15: Rural area | B15: degubra == 3 | J15: 100 | P15: 100 | V15: 100 | AB15: 100 | AH15: 100
A16: Sex
A17: Male | B17: ch117sex == 1 | J17: 100 | P17: 100 | V17: 100 | AB17: 100 | AH17: 100
A18: Female | B18: ch117sex == 2 | J18: 100 | P18: 100 | V18: 100 | AB18: 100 | AH18: 100
A19: Age
A20: 1 | B20: ch117age == 1 | J20: 100 | P20: 100 | V20: 100 | AB20: 100 | AH20: 100
A21: 2 | B21: ch117age == 2 | J21: 100 | P21: 100 | V21: 100 | AB21: 100 | AH21: 100
A22: Education of household head
A23: Primary or less | B23: headed == 1 | J23: 100 | P23: 100 | V23: 100 | AB23: 100 | AH23: 100
A24: Lower secondary | B24: headed == 2 | J24: 100 | P24: 100 | V24: 100 | AB24: 100 | AH24: 100
A25: Upper secondary | B25: headed == 3 | J25: 100 | P25: 100 | V25: 100 | AB25: 100 | AH25: 100
A26: Post secondary+ | B26: headed == 4 | J26: 100 | P26: 100 | V26: 100 | AB26: 100 | AH26: 100
A27: Special education | B27: headed == 5 | J27: 100 | P27: 100 | V27: 100 | AB27: 100 | AH27: 100
A28: Inconsistent / DK / Missing | B28: headed == 8 | J28: 100 | P28: 100 | V28: 100 | AB28: 100 | AH28: 100
A29: Wealth index quintile
A30: Poorest | B30: windex5 == 1 | J30: 100 | P30: 100 | V30: 100 | AB30: 100 | AH30: 100
A31: Second | B31: windex5 == 2 | J31: 100 | P31: 100 | V31: 100 | AB31: 100 | AH31: 100
A32: Middle | B32: windex5 == 3 | J32: 100 | P32: 100 | V32: 100 | AB32: 100 | AH32: 100
A33: Fourth | B33: windex5 == 4 | J33: 100 | P33: 100 | V33: 100 | AB33: 100 | AH33: 100
A34: Richest | B34: windex5 == 5 | J34: 100 | P34: 100 | V34: 100 | AB34: 100 | AH34: 100
A35: A For children age 1-2 years, the recommended daily intake of fruits is two or more servings of fruits per day. A serving = 1 small fruit or 1/2 cup diced pieces of fruits (based on recommendation from "Recommendations for short questions to assess food consumption in children for the NSW Health Surveys" available at https://citeseerx.ist.psu.edu/document?repid=rep1&type=pdf&doi=deaf2bcc2f20c1e2f8bb68da043bc95428e5ab37)..
A36: B For children age 1-2 years, the recommended daily intake of vegetables is three or more servings per day. A serving = 1/4 cup cooked vegetables or 1/2 cup raw vegetables (based on recommendation from "Recommendations for short questions to assess food consumption in children for the NSW Health Surveys" available at https://citeseerx.ist.psu.edu/document?repid=rep1&type=pdf&doi=deaf2bcc2f20c1e2f8bb68da043bc95428e5ab37)..

Sheet JW2.4.3
A1: Table JW2.4.3: Dietary intake (children age 3-17 years) | AH1: IDX
A2: Percentage of children age 3-17 years according to dietary intake, Jamaica MICS Plus 2023-2024, Wave 2
C3: Percentage who: | F3: DK/ Missing | G3: Total | I3: Percentage who: | L3: DK/ Missing | M3: Total | O3: Percentage who eat snacks such as pototo/ banana chips | R3: DK/ Missing | S3: Total | U3: Percentage who eat fast foods such as burgers, pizza, fried chicken | X3: DK/ Missing | Y3: Total | AA3: Percentage who: | AD3: DK/ Missing | AE3: Total | AF3: Number of children age 3-17 years
C4: Don't eat fruits | D4: Eat some fruits but less than the recommended numberA of servings per day | E4: Eat at least the recommended numberA of servings of fruits per day | I4: Don't eat vegetables | J4: Eat some vegetables but less than the recommended numberB of servings per day | K4: Eat at least the recommended numberB of servings of vegetables per day | O4: Once per week or less | P4: 2-4 times per week | Q4: 5 or more times per week | U4: Once per week or less | V4: 2-4 times per week | W4: 5 or more times per week | AA4: Don't drink soda / sugary drinks | AB4: Drink less than 2 cups of soda / sugary drinks per day | AC4: Drink 2 cups or more of soda/sugary drinks per day
B5: hh.sav filter(HH17 %in% c(0,1) & between(RS2B,3,17)) weight by ch117weight | C5: mutate(DI4 = DI4U*100+DI4N) between(DI4,0,100) | D5: DI4 == 101 | between(DI4,201,210) | between(DI4,301,310) | E5: between(DI4,102,120) | F5: DI4 %in% c(199,299,399,998,999) | G5: 100 | I5: mutate(DI6 = DI6U*100+DI6N) between(DI6,0,100) | J5: DI6 %in% c(101,102) | between(DI6,201,210) | between(DI6,301,310) | K5: between(DI6,103,110) | L5: DI6 %in% c(199,299,399,998, 999) | M5: 100 | O5: mutate(DI7 = DI7U*100+DI7N) between(DI7,0,100) | DI7 == 201 | between(DI7,301,304) | P5: between(DI7,202,204) | between(DI7,305,310) | Q5: between(DI7,101,110) | between(DI7,205,210) | R5: DI7 %in% c(199,299,399,998,999) | S5: 100 | U5: mutate(DI8 = DI8U*100+DI8N) between(DI8,0,100) | DI8 == 201 | between(DI8,301,304) | V5: between(DI8,202,204) | between(DI8,305,309) | W5: between(DI8,101,110) | between(DI8,205,210) | X5: DI8 %in% c(199,299,399,998,999) | Y5: 100 | AA5: mutate(DI9 = DI9U*100+DI9N) between(DI9,0,100) | AB5: DI9 == 101 | between(DI9,201,210) | between(DI9,301,324) | AC5: between(DI9,102,123) | DI9 == 230 | AD5: DI9 %in% c(199,299,399,998,999) | AE5: 100 | AF5: total == 1 | AG5: total == 1
A7: Total | B7: total == 1 | C7: p | G7: 100 | I7: p | M7: 100 | O7: p | S7: 100 | U7: p | Y7: 100 | AA7: p | AE7: 100 | AF7: n | AG7: n_unw
A9: Area
A10: Urban | B10: area == 1 | G10: 100 | M10: 100 | S10: 100 | Y10: 100 | AE10: 100
A11: Rural | B11: area == 2 | G11: 100 | M11: 100 | S11: 100 | Y11: 100 | AE11: 100
A12: Degree of urbanization
A13: City | B13: degubra == 1 | G13: 100 | M13: 100 | S13: 100 | Y13: 100 | AE13: 100
A14: Town & Semi-dense area | B14: degubra == 2 | G14: 100 | M14: 100 | S14: 100 | Y14: 100 | AE14: 100
A15: Rural area | B15: degubra == 3 | G15: 100 | M15: 100 | S15: 100 | Y15: 100 | AE15: 100
A16: Sex
A17: Male | B17: ch117sex == 1 | G17: 100 | M17: 100 | S17: 100 | Y17: 100 | AE17: 100
A18: Female | B18: ch117sex == 2 | G18: 100 | M18: 100 | S18: 100 | Y18: 100 | AE18: 100
A19: Age
A20: 3-4 | B20: between(ch117age,3,4) | G20: 100 | M20: 100 | S20: 100 | Y20: 100 | AE20: 100
A21: 5-9 | B21: between(ch117age,5,9) | G21: 100 | M21: 100 | S21: 100 | Y21: 100 | AE21: 100
A22: 10-14 | B22: between(ch117age,10,14) | G22: 100 | M22: 100 | S22: 100 | Y22: 100 | AE22: 100
A23: 15-17 | B23: between(ch117age,15,17) | G23: 100 | M23: 100 | S23: 100 | Y23: 100 | AE23: 100
A24: Education of household head
A25: Primary or less | B25: headed == 1 | G25: 100 | M25: 100 | S25: 100 | Y25: 100 | AE25: 100
A26: Lower secondary | B26: headed == 2 | G26: 100 | M26: 100 | S26: 100 | Y26: 100 | AE26: 100
A27: Upper secondary | B27: headed == 3 | G27: 100 | M27: 100 | S27: 100 | Y27: 100 | AE27: 100
A28: Post secondary+ | B28: headed == 4 | G28: 100 | M28: 100 | S28: 100 | Y28: 100 | AE28: 100
A29: Special education | B29: headed == 5 | G29: 100 | M29: 100 | S29: 100 | Y29: 100 | AE29: 100
A30: Inconsistent / DK / Missing | B30: headed == 8 | G30: 100 | M30: 100 | S30: 100 | Y30: 100 | AE30: 100
A31: Wealth index quintile
A32: Poorest | B32: windex5 == 1 | G32: 100 | M32: 100 | S32: 100 | Y32: 100 | AE32: 100
A33: Second | B33: windex5 == 2 | G33: 100 | M33: 100 | S33: 100 | Y33: 100 | AE33: 100
A34: Middle | B34: windex5 == 3 | G34: 100 | M34: 100 | S34: 100 | Y34: 100 | AE34: 100
A35: Fourth | B35: windex5 == 4 | G35: 100 | M35: 100 | S35: 100 | Y35: 100 | AE35: 100
A36: Richest | B36: windex5 == 5 | G36: 100 | M36: 100 | S36: 100 | Y36: 100 | AE36: 100
A37: A For children age 3-17 years, the recommended daily intake of fruits is two or more servings per day. A serving = 1 medium fruit or 2 small fruits or 1 cup diced pieces of fruit (based on recommendation from "Recommendations for short questions to assess food consumption in children for the NSW Health Surveys" available at https://citeseerx.ist.psu.edu/document?repid=rep1&type=pdf&doi=deaf2bcc2f20c1e2f8bb68da043bc95428e5ab37).s
A38: B For children age 3-17 years, the recommended daily intake of vegetables is three or more servings per day. A serving = 1/2 cup cooked vegetables or 1 cup raw vegetables (based on recommendation from "Recommendations for short questions to assess food consumption in children for the NSW Health Surveys" available at https://citeseerx.ist.psu.edu/document?repid=rep1&type=pdf&doi=deaf2bcc2f20c1e2f8bb68da043bc95428e5ab37)..

Sheet JW2.5.1
A1: Table JW2.5.1 Attitudes toward people with disabilities - Common beliefs | AT1: IDX
A2: Percent distribution of respondentsA by their level of agreementB with statements related to common beliefs about people with disabilitiesC, Samoa MICS Plus 2022-2024, Wave 4
C3: Percent distribution by level of agreement on statements that: | AR3: Number of respondents
C4: People should not expect too much from people with disability | G4: Total | I4: People with disability are easier to take advantage of, exploit or treat badly | M4: Total | O4: People with disability have less to look forward to than others | S4: Total | U4: People with disability should not be optimistic about their future | Y4: Total | AA4: People with disability are a burden on society | AE4: Total | AG4: People with disability are a burden on their families | AK4: Total | AM4: People are inspired by people with disability | AQ4: Total
C5: Agreed | D5: Neither | E5: Disagreed | F5: DK / Missing | I5: Agreed | J5: Neither | K5: Disagreed | L5: DK / Missing | O5: Agreed | P5: Neither | Q5: Disagreed | R5: DK / Missing | U5: Agreed | V5: Neither | W5: Disagreed | X5: DK / Missing | AA5: Agreed | AB5: Neither | AC5: Disagreed | AD5: DK / Missing | AG5: Agreed | AH5: Neither | AI5: Disagreed | AJ5: DK / Missing | AM5: Agreed | AN5: Neither | AO5: Disagreed | AP5: DK / Missing
B6: hh.sav filter(HH17 %in% c(0,1)) weight by hhweight | C6: APD1J %in% c(4,5) | D6: APD1J == 3 | E6: APD1J %in% c(1,2) | F6: APD1J %in% c(8,9) | G6: 100 | I6: APD1F %in% c(4,5) | J6: APD1F == 3 | K6: APD1F %in% c(1,2) | L6: APD1F %in% c(8,9) | M6: 100 | O6: APD1L %in% c(4,5) | P6: APD1L == 3 | Q6: APD1L %in% c(1,2) | R6: APD1L %in% c(8,9) | S6: 100 | U6: APD1K %in% c(4,5) | V6: APD1K == 3 | W6: APD1K %in% c(1,2) | X6: APD1K %in% c(8,9) | Y6: 100 | AA6: APD1C %in% c(4,5) | AB6: APD1C == 3 | AC6: APD1C %in% c(1,2) | AD6: APD1C %in% c(8,9) | AE6: 100 | AG6: APD1D %in% c(4,5) | AH6: APD1D == 3 | AI6: APD1D %in% c(1,2) | AJ6: APD1D %in% c(8,9) | AK6: 100 | AM6: APD2B %in% c(4,5) | AN6: APD2B == 3 | AO6: APD2B %in% c(1,2) | AP6: APD2B %in% c(8,9) | AQ6: 100 | AR6: total == 1 | AS6: total == 1
A8: Total | B8: total == 1 | C8: p | G8: 100 | I8: p | M8: 100 | O8: p | S8: 100 | U8: p | Y8: 100 | AA8: p | AE8: 100 | AG8: p | AK8: 100 | AM8: p | AQ8: 100 | AR8: n | AS8: n_unw
A10: Area
A11: Urban | B11: area == 1 | G11: 100 | M11: 100 | S11: 100 | Y11: 100 | AE11: 100 | AK11: 100 | AQ11: 100
A12: Rural | B12: area == 2 | G12: 100 | M12: 100 | S12: 100 | Y12: 100 | AE12: 100 | AK12: 100 | AQ12: 100
A13: Degree of urbanization
A14: City | B14: degubra == 1 | G14: 100 | M14: 100 | S14: 100 | Y14: 100 | AE14: 100 | AK14: 100 | AQ14: 100
A15: Town & Semi-dense area | B15: degubra == 2 | G15: 100 | M15: 100 | S15: 100 | Y15: 100 | AE15: 100 | AK15: 100 | AQ15: 100
A16: Rural area | B16: degubra == 3 | G16: 100 | M16: 100 | S16: 100 | Y16: 100 | AE16: 100 | AK16: 100 | AQ16: 100
A17: Sex
A18: Male | B18: respsex == 1 | G18: 100 | M18: 100 | S18: 100 | Y18: 100 | AE18: 100 | AK18: 100 | AQ18: 100
A19: Female | B19: respsex == 2 | G19: 100 | M19: 100 | S19: 100 | Y19: 100 | AE19: 100 | AK19: 100 | AQ19: 100
A20: Age
A21: 18-34 | B21: between(respage,18,34) | G21: 100 | M21: 100 | S21: 100 | Y21: 100 | AE21: 100 | AK21: 100 | AQ21: 100
A22: 35-64 | B22: between(respage,35,64) | G22: 100 | M22: 100 | S22: 100 | Y22: 100 | AE22: 100 | AK22: 100 | AQ22: 100
A23: 65-84 | B23: between(respage,65,84) | G23: 100 | M23: 100 | S23: 100 | Y23: 100 | AE23: 100 | AK23: 100 | AQ23: 100
A24: 85+ | B24: between(respage,85,95) | G24: 100 | M24: 100 | S24: 100 | Y24: 100 | AE24: 100 | AK24: 100 | AQ24: 100
A25: Education
A26: Primary or less | B26: resped == 1 | G26: 100 | M26: 100 | S26: 100 | Y26: 100 | AE26: 100 | AK26: 100 | AQ26: 100
A27: Lower secondary | B27: resped == 2 | G27: 100 | M27: 100 | S27: 100 | Y27: 100 | AE27: 100 | AK27: 100 | AQ27: 100
A28: Upper secondary | B28: resped == 3 | G28: 100 | M28: 100 | S28: 100 | Y28: 100 | AE28: 100 | AK28: 100 | AQ28: 100
A29: Post secondary+ | B29: resped == 4 | G29: 100 | M29: 100 | S29: 100 | Y29: 100 | AE29: 100 | AK29: 100 | AQ29: 100
A30: Special education | B30: resped == 5 | G30: 100 | M30: 100 | S30: 100 | Y30: 100 | AE30: 100 | AK30: 100 | AQ30: 100
A31: Inconsistent / DK / Missing | B31: resped == 8 | G31: 100 | M31: 100 | S31: 100 | Y31: 100 | AE31: 100 | AK31: 100 | AQ31: 100
A32: Wealth index quintile
A33: Poorest | B33: windex5 == 1 | G33: 100 | M33: 100 | S33: 100 | Y33: 100 | AE33: 100 | AK33: 100 | AQ33: 100
A34: Second | B34: windex5 == 2 | G34: 100 | M34: 100 | S34: 100 | Y34: 100 | AE34: 100 | AK34: 100 | AQ34: 100
A35: Middle | B35: windex5 == 3 | G35: 100 | M35: 100 | S35: 100 | Y35: 100 | AE35: 100 | AK35: 100 | AQ35: 100
A36: Fourth | B36: windex5 == 4 | G36: 100 | M36: 100 | S36: 100 | Y36: 100 | AE36: 100 | AK36: 100 | AQ36: 100
A37: Richest | B37: windex5 == 5 | G37: 100 | M37: 100 | S37: 100 | Y37: 100 | AE37: 100 | AK37: 100 | AQ37: 100
A38: A In each household, calls were conducted with a “knowledgeable adult household member” who was available at the time of the call. Since respondents were not selected randomly, data based on respondent’s own characteristics, opinions and behavioural patterns may not be representative of the adult population in Samoa
A39: B Responses “agree” and “strongly agree” are combined into a single “agree” category; likewise, “disagree and strongly disagree” are combined into a single “disagree” category
A40: C Survey items from the Attitudes to Disability Scale, developed by Power and Green (Power MJ, Green AM, Group W-D. The Attitudes to Disability Scale (ADS): development and psychometric properties. J Intellect Disabil Res 2010;54(9):860-74). All other survey items were either adapted from existing surveys such as the British Social Attitudes Survey (https://bsa.natcen.ac.uk/), or developed by the survey team.

Sheet JW2.5.2
A1: Table JW2.5.1 Attitudes toward people with disabilities - Attitudes about personal lives | V1: IDX
A2: Percent distribution of respondentsA by their level of agreementB with statements related to attitudes on personal lives of people with disabilitiesC, Samoa MICS Plus 2022-2024, Wave 4
C3: Percent distribution by level of agreement on statements that: | T3: Number of respondents
C4: Sex should not be discussed with people with disability | G4: Total | I4: People believe that people with disability should not raise children | M4: Total | O4: Adults with disability should have a say about who they live with | S4: Total
C5: Agreed | D5: Neither | E5: Disagreed | F5: DK / Missing | I5: Agreed | J5: Neither | K5: Disagreed | L5: DK / Missing | O5: Agreed | P5: Neither | Q5: Disagreed | R5: DK / Missing
B6: hh.sav filter(HH17 %in% c(0,1)) weight by hhweight | C6: APD1I %in% c(4,5) | D6: APD1I == 3 | E6: APD1I %in% c(1,2) | F6: APD1I %in% c(8,9) | G6: 100 | I6: APD2E %in% c(4,5) | J6: APD2E == 3 | K6: APD2E %in% c(1,2) | L6: APD2E %in% c(8,9) | M6: 100 | O6: APD2F %in% c(4,5) | P6: APD2F == 3 | Q6: APD2F %in% c(1,2) | R6: APD2F %in% c(8,9) | S6: 100 | T6: total == 1 | U6: total == 1
A8: Total | B8: total == 1 | C8: p | G8: 100 | I8: p | M8: 100 | O8: p | S8: 100 | T8: n | U8: n_unw
A10: Area
A11: Urban | B11: area == 1 | G11: 100 | M11: 100 | S11: 100
A12: Rural | B12: area == 2 | G12: 100 | M12: 100 | S12: 100
A13: Degree of urbanization
A14: City | B14: degubra == 1 | G14: 100 | M14: 100 | S14: 100
A15: Town & Semi-dense area | B15: degubra == 2 | G15: 100 | M15: 100 | S15: 100
A16: Rural area | B16: degubra == 3 | G16: 100 | M16: 100 | S16: 100
A17: Sex
A18: Male | B18: respsex == 1 | G18: 100 | M18: 100 | S18: 100
A19: Female | B19: respsex == 2 | G19: 100 | M19: 100 | S19: 100
A20: Age
A21: 18-34 | B21: between(respage,18,34) | G21: 100 | M21: 100 | S21: 100
A22: 35-64 | B22: between(respage,35,64) | G22: 100 | M22: 100 | S22: 100
A23: 65-84 | B23: between(respage,65,84) | G23: 100 | M23: 100 | S23: 100
A24: 85+ | B24: between(respage,85,95) | G24: 100 | M24: 100 | S24: 100
A25: Education
A26: Primary or less | B26: resped == 1 | G26: 100 | M26: 100 | S26: 100
A27: Lower secondary | B27: resped == 2 | G27: 100 | M27: 100 | S27: 100
A28: Upper secondary | B28: resped == 3 | G28: 100 | M28: 100 | S28: 100
A29: Post secondary+ | B29: resped == 4 | G29: 100 | M29: 100 | S29: 100
A30: Special education | B30: resped == 5 | G30: 100 | M30: 100 | S30: 100
A31: Inconsistent / DK / Missing | B31: resped == 8 | G31: 100 | M31: 100 | S31: 100
A32: Wealth index quintile
A33: Poorest | B33: windex5 == 1 | G33: 100 | M33: 100 | S33: 100
A34: Second | B34: windex5 == 2 | G34: 100 | M34: 100 | S34: 100
A35: Middle | B35: windex5 == 3 | G35: 100 | M35: 100 | S35: 100
A36: Fourth | B36: windex5 == 4 | G36: 100 | M36: 100 | S36: 100
A37: Richest | B37: windex5 == 5 | G37: 100 | M37: 100 | S37: 100
A38: A In each household, calls were conducted with a “knowledgeable adult household member” who was available at the time of the call. Since respondents were not selected randomly, data based on respondent’s own characteristics, opinions and behavioural patterns may not be representative of the adult population in Samoa
